Workbook

Sheet Cover
C2: TEST CASE
B3: Project Name | C3: DTP | F3: Creator
B4: Project Code | F4: Reviewer/Approver
B5: Document Code | F5: Issue Date
F6: Version | G6: Version 1.3
B7: Purpose of document
B8: Test environment
B9: Record of change
B10: Effective Date | C10: Version | D10: Change Item | E10: *A,D,M | F10: Change description | G10: Reference
B11: 01/10/2026 | C11: 1.0 | D11: Login, Scopes | E11: A | F11: Tạo mới | G11: UC List v2.1, Figma
B12: 02/10/2026 | C12: 1.1 | D12: Tất cả sheet | E12: M | F12: Một màu, một phông | G12: FB-016, FB-019
B13: 02/10/2026 | C13: 1.1 | D13: Login | E13: M | F13: Sửa vùng đếm tổng kết | G13: FB-019
B14: 05/10/2026 | C14: 1.2 | D14: Users, Profile, Cần xác nhận | E14: A | F14: Tạo mới từ UC List v4; nhãn, bố cục chờ Figma trang 02 | G14: UC List v4
B15: 06/10/2026 | C15: 1.3 | D15: Scopes, Login, Users | E15: M | F15: Pre-condition chỉ ghi trạng thái trước khi vào màn đang test, mở màn là Step 1; đổi Name sang giá trị cụ thể ở các case tạo scope | G15: FB-040
B16: 06/10/2026 | C16: 1.3 | D16: Scopes | E16: A | F16: Thêm Scope_130–132; viết lại Scope_021, 022, 025, 026 kiểm tra đủ Type, Name, In scope, Out of scope; thêm Q-S-28 | G16: FB-041
B25: Annotation:
B26: A: Add
B27: D: Delete
B28: M: Modify

Sheet Test_Report
E2: Test Round 1 | N2: Test Round 2 (After fixed bug)
B3: Sheet name | C3: Classification I | D3: Classification II | E3: Executed rate | F3: Executed | G3: Total | H3: Passed | I3: Failed | J3: Pending | K3: Blocked | L3: NA | M3: Not execute | N3: Executed rate | O3: Executed | P3: Total | Q3: Passed | R3: Failed | S3: Pending | T3: Blocked | U3: NA | V3: Not execute
B4: Login | C4: Đăng nhập - Login | D4: Điều hướng - Redirect | E4: =F4/G4 -> 0 | F4: =SUM(H4:L4) -> 0 | G4: =SUM(H4:M4) -> 3 | H4: =COUNTIF(Login!$M$13:$M$15,H$3) -> 0 | I4: =COUNTIF(Login!$M$13:$M$15,I$3) -> 0 | J4: =COUNTIF(Login!$M$13:$M$15,J$3) -> 0 | K4: =COUNTIF(Login!$M$13:$M$15,K$3) -> 0 | L4: =COUNTIF(Login!$M$13:$M$15,L$3) -> 0 | M4: =COUNTA(Login!$G$13:$G$15)-SUM(H4:L4) -> 3 | N4: =O4/P4 -> 0 | O4: =SUM(Q4:U4) -> 0 | P4: =SUM(Q4:V4) -> 3 | Q4: =COUNTIF(Login!$R$13:$R$15,Q$3) -> 0 | R4: =COUNTIF(Login!$R$13:$R$15,R$3) -> 0 | S4: =COUNTIF(Login!$R$13:$R$15,S$3) -> 0 | T4: =COUNTIF(Login!$R$13:$R$15,T$3) -> 0 | U4: =COUNTIF(Login!$R$13:$R$15,U$3) -> 0 | V4: =COUNTA(Login!$G$13:$G$15)-SUM(Q4:U4) -> 3
C5: Đăng nhập - Login | D5: Hiển thị - Display | E5: =F5/G5 -> 0 | F5: =SUM(H5:L5) -> 0 | G5: =SUM(H5:M5) -> 4 | H5: =COUNTIF(Login!$M$16:$M$19,H$3) -> 0 | I5: =COUNTIF(Login!$M$16:$M$19,I$3) -> 0 | J5: =COUNTIF(Login!$M$16:$M$19,J$3) -> 0 | K5: =COUNTIF(Login!$M$16:$M$19,K$3) -> 0 | L5: =COUNTIF(Login!$M$16:$M$19,L$3) -> 0 | M5: =COUNTA(Login!$G$16:$G$19)-SUM(H5:L5) -> 4 | N5: =O5/P5 -> 0 | O5: =SUM(Q5:U5) -> 0 | P5: =SUM(Q5:V5) -> 4 | Q5: =COUNTIF(Login!$R$16:$R$19,Q$3) -> 0 | R5: =COUNTIF(Login!$R$16:$R$19,R$3) -> 0 | S5: =COUNTIF(Login!$R$16:$R$19,S$3) -> 0 | T5: =COUNTIF(Login!$R$16:$R$19,T$3) -> 0 | U5: =COUNTIF(Login!$R$16:$R$19,U$3) -> 0 | V5: =COUNTA(Login!$G$16:$G$19)-SUM(Q5:U5) -> 4
C6: Đăng nhập - Login | D6: Ngôn ngữ - Language | E6: =F6/G6 -> 0 | F6: =SUM(H6:L6) -> 0 | G6: =SUM(H6:M6) -> 4 | H6: =COUNTIF(Login!$M$20:$M$23,H$3) -> 0 | I6: =COUNTIF(Login!$M$20:$M$23,I$3) -> 0 | J6: =COUNTIF(Login!$M$20:$M$23,J$3) -> 0 | K6: =COUNTIF(Login!$M$20:$M$23,K$3) -> 0 | L6: =COUNTIF(Login!$M$20:$M$23,L$3) -> 0 | M6: =COUNTA(Login!$G$20:$G$23)-SUM(H6:L6) -> 4 | N6: =O6/P6 -> 0 | O6: =SUM(Q6:U6) -> 0 | P6: =SUM(Q6:V6) -> 4 | Q6: =COUNTIF(Login!$R$20:$R$23,Q$3) -> 0 | R6: =COUNTIF(Login!$R$20:$R$23,R$3) -> 0 | S6: =COUNTIF(Login!$R$20:$R$23,S$3) -> 0 | T6: =COUNTIF(Login!$R$20:$R$23,T$3) -> 0 | U6: =COUNTIF(Login!$R$20:$R$23,U$3) -> 0 | V6: =COUNTA(Login!$G$20:$G$23)-SUM(Q6:U6) -> 4
C7: Đăng nhập - Login | D7: Email | E7: =F7/G7 -> 0 | F7: =SUM(H7:L7) -> 0 | G7: =SUM(H7:M7) -> 9 | H7: =COUNTIF(Login!$M$24:$M$32,H$3) -> 0 | I7: =COUNTIF(Login!$M$24:$M$32,I$3) -> 0 | J7: =COUNTIF(Login!$M$24:$M$32,J$3) -> 0 | K7: =COUNTIF(Login!$M$24:$M$32,K$3) -> 0 | L7: =COUNTIF(Login!$M$24:$M$32,L$3) -> 0 | M7: =COUNTA(Login!$G$24:$G$32)-SUM(H7:L7) -> 9 | N7: =O7/P7 -> 0 | O7: =SUM(Q7:U7) -> 0 | P7: =SUM(Q7:V7) -> 9 | Q7: =COUNTIF(Login!$R$24:$R$32,Q$3) -> 0 | R7: =COUNTIF(Login!$R$24:$R$32,R$3) -> 0 | S7: =COUNTIF(Login!$R$24:$R$32,S$3) -> 0 | T7: =COUNTIF(Login!$R$24:$R$32,T$3) -> 0 | U7: =COUNTIF(Login!$R$24:$R$32,U$3) -> 0 | V7: =COUNTA(Login!$G$24:$G$32)-SUM(Q7:U7) -> 9
C8: Đăng nhập - Login | D8: Mật khẩu - Password | E8: =F8/G8 -> 0 | F8: =SUM(H8:L8) -> 0 | G8: =SUM(H8:M8) -> 7 | H8: =COUNTIF(Login!$M$33:$M$39,H$3) -> 0 | I8: =COUNTIF(Login!$M$33:$M$39,I$3) -> 0 | J8: =COUNTIF(Login!$M$33:$M$39,J$3) -> 0 | K8: =COUNTIF(Login!$M$33:$M$39,K$3) -> 0 | L8: =COUNTIF(Login!$M$33:$M$39,L$3) -> 0 | M8: =COUNTA(Login!$G$33:$G$39)-SUM(H8:L8) -> 7 | N8: =O8/P8 -> 0 | O8: =SUM(Q8:U8) -> 0 | P8: =SUM(Q8:V8) -> 7 | Q8: =COUNTIF(Login!$R$33:$R$39,Q$3) -> 0 | R8: =COUNTIF(Login!$R$33:$R$39,R$3) -> 0 | S8: =COUNTIF(Login!$R$33:$R$39,S$3) -> 0 | T8: =COUNTIF(Login!$R$33:$R$39,T$3) -> 0 | U8: =COUNTIF(Login!$R$33:$R$39,U$3) -> 0 | V8: =COUNTA(Login!$G$33:$G$39)-SUM(Q8:U8) -> 7
C9: Đăng nhập - Login | D9: Ghi nhớ đăng nhập | E9: =F9/G9 -> 0 | F9: =SUM(H9:L9) -> 0 | G9: =SUM(H9:M9) -> 4 | H9: =COUNTIF(Login!$M$40:$M$43,H$3) -> 0 | I9: =COUNTIF(Login!$M$40:$M$43,I$3) -> 0 | J9: =COUNTIF(Login!$M$40:$M$43,J$3) -> 0 | K9: =COUNTIF(Login!$M$40:$M$43,K$3) -> 0 | L9: =COUNTIF(Login!$M$40:$M$43,L$3) -> 0 | M9: =COUNTA(Login!$G$40:$G$43)-SUM(H9:L9) -> 4 | N9: =O9/P9 -> 0 | O9: =SUM(Q9:U9) -> 0 | P9: =SUM(Q9:V9) -> 4 | Q9: =COUNTIF(Login!$R$40:$R$43,Q$3) -> 0 | R9: =COUNTIF(Login!$R$40:$R$43,R$3) -> 0 | S9: =COUNTIF(Login!$R$40:$R$43,S$3) -> 0 | T9: =COUNTIF(Login!$R$40:$R$43,T$3) -> 0 | U9: =COUNTIF(Login!$R$40:$R$43,U$3) -> 0 | V9: =COUNTA(Login!$G$40:$G$43)-SUM(Q9:U9) -> 4
C10: Đăng nhập - Login | D10: Đăng nhập - Sign in | E10: =F10/G10 -> 0 | F10: =SUM(H10:L10) -> 0 | G10: =SUM(H10:M10) -> 10 | H10: =COUNTIF(Login!$M$44:$M$53,H$3) -> 0 | I10: =COUNTIF(Login!$M$44:$M$53,I$3) -> 0 | J10: =COUNTIF(Login!$M$44:$M$53,J$3) -> 0 | K10: =COUNTIF(Login!$M$44:$M$53,K$3) -> 0 | L10: =COUNTIF(Login!$M$44:$M$53,L$3) -> 0 | M10: =COUNTA(Login!$G$44:$G$53)-SUM(H10:L10) -> 10 | N10: =O10/P10 -> 0 | O10: =SUM(Q10:U10) -> 0 | P10: =SUM(Q10:V10) -> 10 | Q10: =COUNTIF(Login!$R$44:$R$53,Q$3) -> 0 | R10: =COUNTIF(Login!$R$44:$R$53,R$3) -> 0 | S10: =COUNTIF(Login!$R$44:$R$53,S$3) -> 0 | T10: =COUNTIF(Login!$R$44:$R$53,T$3) -> 0 | U10: =COUNTIF(Login!$R$44:$R$53,U$3) -> 0 | V10: =COUNTA(Login!$G$44:$G$53)-SUM(Q10:U10) -> 10
C11: Đăng nhập - Login | D11: Nút Sign in | E11: =F11/G11 -> 0 | F11: =SUM(H11:L11) -> 0 | G11: =SUM(H11:M11) -> 3 | H11: =COUNTIF(Login!$M$54:$M$56,H$3) -> 0 | I11: =COUNTIF(Login!$M$54:$M$56,I$3) -> 0 | J11: =COUNTIF(Login!$M$54:$M$56,J$3) -> 0 | K11: =COUNTIF(Login!$M$54:$M$56,K$3) -> 0 | L11: =COUNTIF(Login!$M$54:$M$56,L$3) -> 0 | M11: =COUNTA(Login!$G$54:$G$56)-SUM(H11:L11) -> 3 | N11: =O11/P11 -> 0 | O11: =SUM(Q11:U11) -> 0 | P11: =SUM(Q11:V11) -> 3 | Q11: =COUNTIF(Login!$R$54:$R$56,Q$3) -> 0 | R11: =COUNTIF(Login!$R$54:$R$56,R$3) -> 0 | S11: =COUNTIF(Login!$R$54:$R$56,S$3) -> 0 | T11: =COUNTIF(Login!$R$54:$R$56,T$3) -> 0 | U11: =COUNTIF(Login!$R$54:$R$56,U$3) -> 0 | V11: =COUNTA(Login!$G$54:$G$56)-SUM(Q11:U11) -> 3
C12: Đăng nhập - Login | D12: Hỗ trợ - Support | E12: =F12/G12 -> 0 | F12: =SUM(H12:L12) -> 0 | G12: =SUM(H12:M12) -> 3 | H12: =COUNTIF(Login!$M$57:$M$59,H$3) -> 0 | I12: =COUNTIF(Login!$M$57:$M$59,I$3) -> 0 | J12: =COUNTIF(Login!$M$57:$M$59,J$3) -> 0 | K12: =COUNTIF(Login!$M$57:$M$59,K$3) -> 0 | L12: =COUNTIF(Login!$M$57:$M$59,L$3) -> 0 | M12: =COUNTA(Login!$G$57:$G$59)-SUM(H12:L12) -> 3 | N12: =O12/P12 -> 0 | O12: =SUM(Q12:U12) -> 0 | P12: =SUM(Q12:V12) -> 3 | Q12: =COUNTIF(Login!$R$57:$R$59,Q$3) -> 0 | R12: =COUNTIF(Login!$R$57:$R$59,R$3) -> 0 | S12: =COUNTIF(Login!$R$57:$R$59,S$3) -> 0 | T12: =COUNTIF(Login!$R$57:$R$59,T$3) -> 0 | U12: =COUNTIF(Login!$R$57:$R$59,U$3) -> 0 | V12: =COUNTA(Login!$G$57:$G$59)-SUM(Q12:U12) -> 3
C13: Đăng nhập - Login | D13: Bảo mật - Security | E13: =F13/G13 -> 0 | F13: =SUM(H13:L13) -> 0 | G13: =SUM(H13:M13) -> 5 | H13: =COUNTIF(Login!$M$60:$M$64,H$3) -> 0 | I13: =COUNTIF(Login!$M$60:$M$64,I$3) -> 0 | J13: =COUNTIF(Login!$M$60:$M$64,J$3) -> 0 | K13: =COUNTIF(Login!$M$60:$M$64,K$3) -> 0 | L13: =COUNTIF(Login!$M$60:$M$64,L$3) -> 0 | M13: =COUNTA(Login!$G$60:$G$64)-SUM(H13:L13) -> 5 | N13: =O13/P13 -> 0 | O13: =SUM(Q13:U13) -> 0 | P13: =SUM(Q13:V13) -> 5 | Q13: =COUNTIF(Login!$R$60:$R$64,Q$3) -> 0 | R13: =COUNTIF(Login!$R$60:$R$64,R$3) -> 0 | S13: =COUNTIF(Login!$R$60:$R$64,S$3) -> 0 | T13: =COUNTIF(Login!$R$60:$R$64,T$3) -> 0 | U13: =COUNTIF(Login!$R$60:$R$64,U$3) -> 0 | V13: =COUNTA(Login!$G$60:$G$64)-SUM(Q13:U13) -> 5
C14: Total | E14: =F14/G14 -> 0 | F14: =SUM(H14:L14) -> 0 | G14: =SUM(H14:M14) -> 52 | H14: =SUM(H4:H13) -> 0 | I14: =SUM(I4:I13) -> 0 | J14: =SUM(J4:J13) -> 0 | K14: =SUM(K4:K13) -> 0 | L14: =SUM(L4:L13) -> 0 | M14: =SUM(M4:M13) -> 52 | N14: =O14/P14 -> 0 | O14: =SUM(Q14:U14) -> 0 | P14: =SUM(Q14:V14) -> 52 | Q14: =SUM(Q4:Q13) -> 0 | R14: =SUM(R4:R13) -> 0 | S14: =SUM(S4:S13) -> 0 | T14: =SUM(T4:T13) -> 0 | U14: =SUM(U4:U13) -> 0 | V14: =SUM(V4:V13) -> 52
B15: Scopes | C15: Điều hướng - Redirect | D15: Vào danh sách - Scope list | E15: =F15/G15 -> 0 | F15: =SUM(H15:L15) -> 0 | G15: =SUM(H15:M15) -> 2 | H15: =COUNTIF(Scopes!$M$13:$M$14,H$3) -> 0 | I15: =COUNTIF(Scopes!$M$13:$M$14,I$3) -> 0 | J15: =COUNTIF(Scopes!$M$13:$M$14,J$3) -> 0 | K15: =COUNTIF(Scopes!$M$13:$M$14,K$3) -> 0 | L15: =COUNTIF(Scopes!$M$13:$M$14,L$3) -> 0 | M15: =COUNTA(Scopes!$G$13:$G$14)-SUM(H15:L15) -> 2 | N15: =O15/P15 -> 0 | O15: =SUM(Q15:U15) -> 0 | P15: =SUM(Q15:V15) -> 2 | Q15: =COUNTIF(Scopes!$R$13:$R$14,Q$3) -> 0 | R15: =COUNTIF(Scopes!$R$13:$R$14,R$3) -> 0 | S15: =COUNTIF(Scopes!$R$13:$R$14,S$3) -> 0 | T15: =COUNTIF(Scopes!$R$13:$R$14,T$3) -> 0 | U15: =COUNTIF(Scopes!$R$13:$R$14,U$3) -> 0 | V15: =COUNTA(Scopes!$G$13:$G$14)-SUM(Q15:U15) -> 2
C16: Điều hướng - Redirect | D16: Vào chi tiết - Scope detail | E16: =F16/G16 -> 0 | F16: =SUM(H16:L16) -> 0 | G16: =SUM(H16:M16) -> 3 | H16: =COUNTIF(Scopes!$M$15:$M$17,H$3) -> 0 | I16: =COUNTIF(Scopes!$M$15:$M$17,I$3) -> 0 | J16: =COUNTIF(Scopes!$M$15:$M$17,J$3) -> 0 | K16: =COUNTIF(Scopes!$M$15:$M$17,K$3) -> 0 | L16: =COUNTIF(Scopes!$M$15:$M$17,L$3) -> 0 | M16: =COUNTA(Scopes!$G$15:$G$17)-SUM(H16:L16) -> 3 | N16: =O16/P16 -> 0 | O16: =SUM(Q16:U16) -> 0 | P16: =SUM(Q16:V16) -> 3 | Q16: =COUNTIF(Scopes!$R$15:$R$17,Q$3) -> 0 | R16: =COUNTIF(Scopes!$R$15:$R$17,R$3) -> 0 | S16: =COUNTIF(Scopes!$R$15:$R$17,S$3) -> 0 | T16: =COUNTIF(Scopes!$R$15:$R$17,T$3) -> 0 | U16: =COUNTIF(Scopes!$R$15:$R$17,U$3) -> 0 | V16: =COUNTA(Scopes!$G$15:$G$17)-SUM(Q16:U16) -> 3
C17: Danh sách scope - Scope list | D17: Tiêu đề trang - Title | E17: =F17/G17 -> 0 | F17: =SUM(H17:L17) -> 0 | G17: =SUM(H17:M17) -> 1 | H17: =COUNTIF(Scopes!$M$18:$M$18,H$3) -> 0 | I17: =COUNTIF(Scopes!$M$18:$M$18,I$3) -> 0 | J17: =COUNTIF(Scopes!$M$18:$M$18,J$3) -> 0 | K17: =COUNTIF(Scopes!$M$18:$M$18,K$3) -> 0 | L17: =COUNTIF(Scopes!$M$18:$M$18,L$3) -> 0 | M17: =COUNTA(Scopes!$G$18:$G$18)-SUM(H17:L17) -> 1 | N17: =O17/P17 -> 0 | O17: =SUM(Q17:U17) -> 0 | P17: =SUM(Q17:V17) -> 1 | Q17: =COUNTIF(Scopes!$R$18:$R$18,Q$3) -> 0 | R17: =COUNTIF(Scopes!$R$18:$R$18,R$3) -> 0 | S17: =COUNTIF(Scopes!$R$18:$R$18,S$3) -> 0 | T17: =COUNTIF(Scopes!$R$18:$R$18,T$3) -> 0 | U17: =COUNTIF(Scopes!$R$18:$R$18,U$3) -> 0 | V17: =COUNTA(Scopes!$G$18:$G$18)-SUM(Q17:U17) -> 1
C18: Danh sách scope - Scope list | D18: Tạo scope - Create scope | E18: =F18/G18 -> 0 | F18: =SUM(H18:L18) -> 0 | G18: =SUM(H18:M18) -> 20 | H18: =COUNTIF(Scopes!$M$20:$M$39,H$3) -> 0 | I18: =COUNTIF(Scopes!$M$20:$M$39,I$3) -> 0 | J18: =COUNTIF(Scopes!$M$20:$M$39,J$3) -> 0 | K18: =COUNTIF(Scopes!$M$20:$M$39,K$3) -> 0 | L18: =COUNTIF(Scopes!$M$20:$M$39,L$3) -> 0 | M18: =COUNTA(Scopes!$G$20:$G$39)-SUM(H18:L18) -> 20 | N18: =O18/P18 -> 0 | O18: =SUM(Q18:U18) -> 0 | P18: =SUM(Q18:V18) -> 20 | Q18: =COUNTIF(Scopes!$R$20:$R$39,Q$3) -> 0 | R18: =COUNTIF(Scopes!$R$20:$R$39,R$3) -> 0 | S18: =COUNTIF(Scopes!$R$20:$R$39,S$3) -> 0 | T18: =COUNTIF(Scopes!$R$20:$R$39,T$3) -> 0 | U18: =COUNTIF(Scopes!$R$20:$R$39,U$3) -> 0 | V18: =COUNTA(Scopes!$G$20:$G$39)-SUM(Q18:U18) -> 20
C19: Danh sách scope - Scope list | D19: Thanh công cụ - Toolbar | E19: =F19/G19 -> 0 | F19: =SUM(H19:L19) -> 0 | G19: =SUM(H19:M19) -> 7 | H19: =COUNTIF(Scopes!$M$40:$M$46,H$3) -> 0 | I19: =COUNTIF(Scopes!$M$40:$M$46,I$3) -> 0 | J19: =COUNTIF(Scopes!$M$40:$M$46,J$3) -> 0 | K19: =COUNTIF(Scopes!$M$40:$M$46,K$3) -> 0 | L19: =COUNTIF(Scopes!$M$40:$M$46,L$3) -> 0 | M19: =COUNTA(Scopes!$G$40:$G$46)-SUM(H19:L19) -> 7 | N19: =O19/P19 -> 0 | O19: =SUM(Q19:U19) -> 0 | P19: =SUM(Q19:V19) -> 7 | Q19: =COUNTIF(Scopes!$R$40:$R$46,Q$3) -> 0 | R19: =COUNTIF(Scopes!$R$40:$R$46,R$3) -> 0 | S19: =COUNTIF(Scopes!$R$40:$R$46,S$3) -> 0 | T19: =COUNTIF(Scopes!$R$40:$R$46,T$3) -> 0 | U19: =COUNTIF(Scopes!$R$40:$R$46,U$3) -> 0 | V19: =COUNTA(Scopes!$G$40:$G$46)-SUM(Q19:U19) -> 7
C20: Danh sách scope - Scope list | D20: Bảng danh sách - Table | E20: =F20/G20 -> 0 | F20: =SUM(H20:L20) -> 0 | G20: =SUM(H20:M20) -> 12 | H20: =COUNTIF(Scopes!$M$47:$M$64,H$3) -> 0 | I20: =COUNTIF(Scopes!$M$47:$M$64,I$3) -> 0 | J20: =COUNTIF(Scopes!$M$47:$M$64,J$3) -> 0 | K20: =COUNTIF(Scopes!$M$47:$M$64,K$3) -> 0 | L20: =COUNTIF(Scopes!$M$47:$M$64,L$3) -> 0 | M20: =COUNTA(Scopes!$G$47:$G$64)-SUM(H20:L20) -> 12 | N20: =O20/P20 -> 0 | O20: =SUM(Q20:U20) -> 0 | P20: =SUM(Q20:V20) -> 12 | Q20: =COUNTIF(Scopes!$R$47:$R$64,Q$3) -> 0 | R20: =COUNTIF(Scopes!$R$47:$R$64,R$3) -> 0 | S20: =COUNTIF(Scopes!$R$47:$R$64,S$3) -> 0 | T20: =COUNTIF(Scopes!$R$47:$R$64,T$3) -> 0 | U20: =COUNTIF(Scopes!$R$47:$R$64,U$3) -> 0 | V20: =COUNTA(Scopes!$G$47:$G$64)-SUM(Q20:U20) -> 12
C21: Danh sách scope - Scope list | D21: Phân trang - Paging | E21: =F21/G21 -> 0 | F21: =SUM(H21:L21) -> 0 | G21: =SUM(H21:M21) -> 4 | H21: =COUNTIF(Scopes!$M$65:$M$69,H$3) -> 0 | I21: =COUNTIF(Scopes!$M$65:$M$69,I$3) -> 0 | J21: =COUNTIF(Scopes!$M$65:$M$69,J$3) -> 0 | K21: =COUNTIF(Scopes!$M$65:$M$69,K$3) -> 0 | L21: =COUNTIF(Scopes!$M$65:$M$69,L$3) -> 0 | M21: =COUNTA(Scopes!$G$65:$G$69)-SUM(H21:L21) -> 4 | N21: =O21/P21 -> 0 | O21: =SUM(Q21:U21) -> 0 | P21: =SUM(Q21:V21) -> 4 | Q21: =COUNTIF(Scopes!$R$65:$R$69,Q$3) -> 0 | R21: =COUNTIF(Scopes!$R$65:$R$69,R$3) -> 0 | S21: =COUNTIF(Scopes!$R$65:$R$69,S$3) -> 0 | T21: =COUNTIF(Scopes!$R$65:$R$69,T$3) -> 0 | U21: =COUNTIF(Scopes!$R$65:$R$69,U$3) -> 0 | V21: =COUNTA(Scopes!$G$65:$G$69)-SUM(Q21:U21) -> 4
C22: Danh sách scope - Scope list | D22: Trạng thái rỗng - Empty | E22: =F22/G22 -> 0 | F22: =SUM(H22:L22) -> 0 | G22: =SUM(H22:M22) -> 1 | H22: =COUNTIF(Scopes!$M$19,H$3) -> 0 | I22: =COUNTIF(Scopes!$M$19,I$3) -> 0 | J22: =COUNTIF(Scopes!$M$19,J$3) -> 0 | K22: =COUNTIF(Scopes!$M$19,K$3) -> 0 | L22: =COUNTIF(Scopes!$M$19,L$3) -> 0 | M22: =COUNTA(Scopes!$G$19)-SUM(H22:L22) -> 1 | N22: =O22/P22 -> 0 | O22: =SUM(Q22:U22) -> 0 | P22: =SUM(Q22:V22) -> 1 | Q22: =COUNTIF(Scopes!$R$19,Q$3) -> 0 | R22: =COUNTIF(Scopes!$R$19,R$3) -> 0 | S22: =COUNTIF(Scopes!$R$19,S$3) -> 0 | T22: =COUNTIF(Scopes!$R$19,T$3) -> 0 | U22: =COUNTIF(Scopes!$R$19,U$3) -> 0 | V22: =COUNTA(Scopes!$G$19)-SUM(Q22:U22) -> 1
C23: Chi tiết scope - Scope detail | D23: Phần đầu - Header | E23: =F23/G23 -> 0 | F23: =SUM(H23:L23) -> 0 | G23: =SUM(H23:M23) -> 5 | H23: =COUNTIF(Scopes!$M$70:$M$76,H$3) -> 0 | I23: =COUNTIF(Scopes!$M$70:$M$76,I$3) -> 0 | J23: =COUNTIF(Scopes!$M$70:$M$76,J$3) -> 0 | K23: =COUNTIF(Scopes!$M$70:$M$76,K$3) -> 0 | L23: =COUNTIF(Scopes!$M$70:$M$76,L$3) -> 0 | M23: =COUNTA(Scopes!$G$70:$G$76)-SUM(H23:L23) -> 5 | N23: =O23/P23 -> 0 | O23: =SUM(Q23:U23) -> 0 | P23: =SUM(Q23:V23) -> 5 | Q23: =COUNTIF(Scopes!$R$70:$R$76,Q$3) -> 0 | R23: =COUNTIF(Scopes!$R$70:$R$76,R$3) -> 0 | S23: =COUNTIF(Scopes!$R$70:$R$76,S$3) -> 0 | T23: =COUNTIF(Scopes!$R$70:$R$76,T$3) -> 0 | U23: =COUNTIF(Scopes!$R$70:$R$76,U$3) -> 0 | V23: =COUNTA(Scopes!$G$70:$G$76)-SUM(Q23:U23) -> 5
C24: Chi tiết scope - Scope detail | D24: Điều hướng trong màn - Section nav | E24: =F24/G24 -> 0 | F24: =SUM(H24:L24) -> 0 | G24: =SUM(H24:M24) -> 2 | H24: =COUNTIF(Scopes!$M$77:$M$78,H$3) -> 0 | I24: =COUNTIF(Scopes!$M$77:$M$78,I$3) -> 0 | J24: =COUNTIF(Scopes!$M$77:$M$78,J$3) -> 0 | K24: =COUNTIF(Scopes!$M$77:$M$78,K$3) -> 0 | L24: =COUNTIF(Scopes!$M$77:$M$78,L$3) -> 0 | M24: =COUNTA(Scopes!$G$77:$G$78)-SUM(H24:L24) -> 2 | N24: =O24/P24 -> 0 | O24: =SUM(Q24:U24) -> 0 | P24: =SUM(Q24:V24) -> 2 | Q24: =COUNTIF(Scopes!$R$77:$R$78,Q$3) -> 0 | R24: =COUNTIF(Scopes!$R$77:$R$78,R$3) -> 0 | S24: =COUNTIF(Scopes!$R$77:$R$78,S$3) -> 0 | T24: =COUNTIF(Scopes!$R$77:$R$78,T$3) -> 0 | U24: =COUNTIF(Scopes!$R$77:$R$78,U$3) -> 0 | V24: =COUNTA(Scopes!$G$77:$G$78)-SUM(Q24:U24) -> 2
C25: Chi tiết scope - Scope detail | D25: Tổng quan - Overview | E25: =F25/G25 -> 0 | F25: =SUM(H25:L25) -> 0 | G25: =SUM(H25:M25) -> 4 | H25: =COUNTIF(Scopes!$M$79:$M$82,H$3) -> 0 | I25: =COUNTIF(Scopes!$M$79:$M$82,I$3) -> 0 | J25: =COUNTIF(Scopes!$M$79:$M$82,J$3) -> 0 | K25: =COUNTIF(Scopes!$M$79:$M$82,K$3) -> 0 | L25: =COUNTIF(Scopes!$M$79:$M$82,L$3) -> 0 | M25: =COUNTA(Scopes!$G$79:$G$82)-SUM(H25:L25) -> 4 | N25: =O25/P25 -> 0 | O25: =SUM(Q25:U25) -> 0 | P25: =SUM(Q25:V25) -> 4 | Q25: =COUNTIF(Scopes!$R$79:$R$82,Q$3) -> 0 | R25: =COUNTIF(Scopes!$R$79:$R$82,R$3) -> 0 | S25: =COUNTIF(Scopes!$R$79:$R$82,S$3) -> 0 | T25: =COUNTIF(Scopes!$R$79:$R$82,T$3) -> 0 | U25: =COUNTIF(Scopes!$R$79:$R$82,U$3) -> 0 | V25: =COUNTA(Scopes!$G$79:$G$82)-SUM(Q25:U25) -> 4
C26: Chi tiết scope - Scope detail | D26: Sửa scope - Edit scope | E26: =F26/G26 -> 0 | F26: =SUM(H26:L26) -> 0 | G26: =SUM(H26:M26) -> 11 | H26: =COUNTIF(Scopes!$M$83:$M$93,H$3) -> 0 | I26: =COUNTIF(Scopes!$M$83:$M$93,I$3) -> 0 | J26: =COUNTIF(Scopes!$M$83:$M$93,J$3) -> 0 | K26: =COUNTIF(Scopes!$M$83:$M$93,K$3) -> 0 | L26: =COUNTIF(Scopes!$M$83:$M$93,L$3) -> 0 | M26: =COUNTA(Scopes!$G$83:$G$93)-SUM(H26:L26) -> 11 | N26: =O26/P26 -> 0 | O26: =SUM(Q26:U26) -> 0 | P26: =SUM(Q26:V26) -> 11 | Q26: =COUNTIF(Scopes!$R$83:$R$93,Q$3) -> 0 | R26: =COUNTIF(Scopes!$R$83:$R$93,R$3) -> 0 | S26: =COUNTIF(Scopes!$R$83:$R$93,S$3) -> 0 | T26: =COUNTIF(Scopes!$R$83:$R$93,T$3) -> 0 | U26: =COUNTIF(Scopes!$R$83:$R$93,U$3) -> 0 | V26: =COUNTA(Scopes!$G$83:$G$93)-SUM(Q26:U26) -> 11
C27: Chi tiết scope - Scope detail | D27: Khối Frameworks - Frameworks | E27: =F27/G27 -> 0 | F27: =SUM(H27:L27) -> 0 | G27: =SUM(H27:M27) -> 7 | H27: =COUNTIF(Scopes!$M$94:$M$100,H$3) -> 0 | I27: =COUNTIF(Scopes!$M$94:$M$100,I$3) -> 0 | J27: =COUNTIF(Scopes!$M$94:$M$100,J$3) -> 0 | K27: =COUNTIF(Scopes!$M$94:$M$100,K$3) -> 0 | L27: =COUNTIF(Scopes!$M$94:$M$100,L$3) -> 0 | M27: =COUNTA(Scopes!$G$94:$G$100)-SUM(H27:L27) -> 7 | N27: =O27/P27 -> 0 | O27: =SUM(Q27:U27) -> 0 | P27: =SUM(Q27:V27) -> 7 | Q27: =COUNTIF(Scopes!$R$94:$R$100,Q$3) -> 0 | R27: =COUNTIF(Scopes!$R$94:$R$100,R$3) -> 0 | S27: =COUNTIF(Scopes!$R$94:$R$100,S$3) -> 0 | T27: =COUNTIF(Scopes!$R$94:$R$100,T$3) -> 0 | U27: =COUNTIF(Scopes!$R$94:$R$100,U$3) -> 0 | V27: =COUNTA(Scopes!$G$94:$G$100)-SUM(Q27:U27) -> 7
C28: Chi tiết scope - Scope detail | D28: Gắn framework - Link framework | E28: =F28/G28 -> 0 | F28: =SUM(H28:L28) -> 0 | G28: =SUM(H28:M28) -> 13 | H28: =COUNTIF(Scopes!$M$101:$M$113,H$3) -> 0 | I28: =COUNTIF(Scopes!$M$101:$M$113,I$3) -> 0 | J28: =COUNTIF(Scopes!$M$101:$M$113,J$3) -> 0 | K28: =COUNTIF(Scopes!$M$101:$M$113,K$3) -> 0 | L28: =COUNTIF(Scopes!$M$101:$M$113,L$3) -> 0 | M28: =COUNTA(Scopes!$G$101:$G$113)-SUM(H28:L28) -> 13 | N28: =O28/P28 -> 0 | O28: =SUM(Q28:U28) -> 0 | P28: =SUM(Q28:V28) -> 13 | Q28: =COUNTIF(Scopes!$R$101:$R$113,Q$3) -> 0 | R28: =COUNTIF(Scopes!$R$101:$R$113,R$3) -> 0 | S28: =COUNTIF(Scopes!$R$101:$R$113,S$3) -> 0 | T28: =COUNTIF(Scopes!$R$101:$R$113,T$3) -> 0 | U28: =COUNTIF(Scopes!$R$101:$R$113,U$3) -> 0 | V28: =COUNTA(Scopes!$G$101:$G$113)-SUM(Q28:U28) -> 13
C29: Chi tiết scope - Scope detail | D29: Gỡ framework - Unlink framework | E29: =F29/G29 -> 0 | F29: =SUM(H29:L29) -> 0 | G29: =SUM(H29:M29) -> 1 | H29: =COUNTIF(Scopes!$M$114,H$3) -> 0 | I29: =COUNTIF(Scopes!$M$114,I$3) -> 0 | J29: =COUNTIF(Scopes!$M$114,J$3) -> 0 | K29: =COUNTIF(Scopes!$M$114,K$3) -> 0 | L29: =COUNTIF(Scopes!$M$114,L$3) -> 0 | M29: =COUNTA(Scopes!$G$114)-SUM(H29:L29) -> 1 | N29: =O29/P29 -> 0 | O29: =SUM(Q29:U29) -> 0 | P29: =SUM(Q29:V29) -> 1 | Q29: =COUNTIF(Scopes!$R$114,Q$3) -> 0 | R29: =COUNTIF(Scopes!$R$114,R$3) -> 0 | S29: =COUNTIF(Scopes!$R$114,S$3) -> 0 | T29: =COUNTIF(Scopes!$R$114,T$3) -> 0 | U29: =COUNTIF(Scopes!$R$114,U$3) -> 0 | V29: =COUNTA(Scopes!$G$114)-SUM(Q29:U29) -> 1
C30: Chi tiết scope - Scope detail | D30: Đổi tier - Change tier | E30: =F30/G30 -> 0 | F30: =SUM(H30:L30) -> 0 | G30: =SUM(H30:M30) -> 6 | H30: =COUNTIF(Scopes!$M$115:$M$120,H$3) -> 0 | I30: =COUNTIF(Scopes!$M$115:$M$120,I$3) -> 0 | J30: =COUNTIF(Scopes!$M$115:$M$120,J$3) -> 0 | K30: =COUNTIF(Scopes!$M$115:$M$120,K$3) -> 0 | L30: =COUNTIF(Scopes!$M$115:$M$120,L$3) -> 0 | M30: =COUNTA(Scopes!$G$115:$G$120)-SUM(H30:L30) -> 6 | N30: =O30/P30 -> 0 | O30: =SUM(Q30:U30) -> 0 | P30: =SUM(Q30:V30) -> 6 | Q30: =COUNTIF(Scopes!$R$115:$R$120,Q$3) -> 0 | R30: =COUNTIF(Scopes!$R$115:$R$120,R$3) -> 0 | S30: =COUNTIF(Scopes!$R$115:$R$120,S$3) -> 0 | T30: =COUNTIF(Scopes!$R$115:$R$120,T$3) -> 0 | U30: =COUNTIF(Scopes!$R$115:$R$120,U$3) -> 0 | V30: =COUNTA(Scopes!$G$115:$G$120)-SUM(Q30:U30) -> 6
C31: Chi tiết scope - Scope detail | D31: Khối Users - Users | E31: =F31/G31 -> 0 | F31: =SUM(H31:L31) -> 0 | G31: =SUM(H31:M31) -> 3 | H31: =COUNTIF(Scopes!$M$121:$M$123,H$3) -> 0 | I31: =COUNTIF(Scopes!$M$121:$M$123,I$3) -> 0 | J31: =COUNTIF(Scopes!$M$121:$M$123,J$3) -> 0 | K31: =COUNTIF(Scopes!$M$121:$M$123,K$3) -> 0 | L31: =COUNTIF(Scopes!$M$121:$M$123,L$3) -> 0 | M31: =COUNTA(Scopes!$G$121:$G$123)-SUM(H31:L31) -> 3 | N31: =O31/P31 -> 0 | O31: =SUM(Q31:U31) -> 0 | P31: =SUM(Q31:V31) -> 3 | Q31: =COUNTIF(Scopes!$R$121:$R$123,Q$3) -> 0 | R31: =COUNTIF(Scopes!$R$121:$R$123,R$3) -> 0 | S31: =COUNTIF(Scopes!$R$121:$R$123,S$3) -> 0 | T31: =COUNTIF(Scopes!$R$121:$R$123,T$3) -> 0 | U31: =COUNTIF(Scopes!$R$121:$R$123,U$3) -> 0 | V31: =COUNTA(Scopes!$G$121:$G$123)-SUM(Q31:U31) -> 3
C32: Chi tiết scope - Scope detail | D32: Gán người dùng - Assign users | E32: =F32/G32 -> 0 | F32: =SUM(H32:L32) -> 0 | G32: =SUM(H32:M32) -> 9 | H32: =COUNTIF(Scopes!$M$124:$M$132,H$3) -> 0 | I32: =COUNTIF(Scopes!$M$124:$M$132,I$3) -> 0 | J32: =COUNTIF(Scopes!$M$124:$M$132,J$3) -> 0 | K32: =COUNTIF(Scopes!$M$124:$M$132,K$3) -> 0 | L32: =COUNTIF(Scopes!$M$124:$M$132,L$3) -> 0 | M32: =COUNTA(Scopes!$G$124:$G$132)-SUM(H32:L32) -> 9 | N32: =O32/P32 -> 0 | O32: =SUM(Q32:U32) -> 0 | P32: =SUM(Q32:V32) -> 9 | Q32: =COUNTIF(Scopes!$R$124:$R$132,Q$3) -> 0 | R32: =COUNTIF(Scopes!$R$124:$R$132,R$3) -> 0 | S32: =COUNTIF(Scopes!$R$124:$R$132,S$3) -> 0 | T32: =COUNTIF(Scopes!$R$124:$R$132,T$3) -> 0 | U32: =COUNTIF(Scopes!$R$124:$R$132,U$3) -> 0 | V32: =COUNTA(Scopes!$G$124:$G$132)-SUM(Q32:U32) -> 9
C33: Chi tiết scope - Scope detail | D33: Tổng hợp - Summary | E33: =F33/G33 -> 0 | F33: =SUM(H33:L33) -> 0 | G33: =SUM(H33:M33) -> 1 | H33: =COUNTIF(Scopes!$M$133,H$3) -> 0 | I33: =COUNTIF(Scopes!$M$133,I$3) -> 0 | J33: =COUNTIF(Scopes!$M$133,J$3) -> 0 | K33: =COUNTIF(Scopes!$M$133,K$3) -> 0 | L33: =COUNTIF(Scopes!$M$133,L$3) -> 0 | M33: =COUNTA(Scopes!$G$133)-SUM(H33:L33) -> 1 | N33: =O33/P33 -> 0 | O33: =SUM(Q33:U33) -> 0 | P33: =SUM(Q33:V33) -> 1 | Q33: =COUNTIF(Scopes!$R$133,Q$3) -> 0 | R33: =COUNTIF(Scopes!$R$133,R$3) -> 0 | S33: =COUNTIF(Scopes!$R$133,S$3) -> 0 | T33: =COUNTIF(Scopes!$R$133,T$3) -> 0 | U33: =COUNTIF(Scopes!$R$133,U$3) -> 0 | V33: =COUNTA(Scopes!$G$133)-SUM(Q33:U33) -> 1
C34: Phân quyền - Permission | D34: Customer User | E34: =F34/G34 -> 0 | F34: =SUM(H34:L34) -> 0 | G34: =SUM(H34:M34) -> 6 | H34: =COUNTIF(Scopes!$M$134:$M$139,H$3) -> 0 | I34: =COUNTIF(Scopes!$M$134:$M$139,I$3) -> 0 | J34: =COUNTIF(Scopes!$M$134:$M$139,J$3) -> 0 | K34: =COUNTIF(Scopes!$M$134:$M$139,K$3) -> 0 | L34: =COUNTIF(Scopes!$M$134:$M$139,L$3) -> 0 | M34: =COUNTA(Scopes!$G$134:$G$139)-SUM(H34:L34) -> 6 | N34: =O34/P34 -> 0 | O34: =SUM(Q34:U34) -> 0 | P34: =SUM(Q34:V34) -> 6 | Q34: =COUNTIF(Scopes!$R$134:$R$139,Q$3) -> 0 | R34: =COUNTIF(Scopes!$R$134:$R$139,R$3) -> 0 | S34: =COUNTIF(Scopes!$R$134:$R$139,S$3) -> 0 | T34: =COUNTIF(Scopes!$R$134:$R$139,T$3) -> 0 | U34: =COUNTIF(Scopes!$R$134:$R$139,U$3) -> 0 | V34: =COUNTA(Scopes!$G$134:$G$139)-SUM(Q34:U34) -> 6
C35: Phân quyền - Permission | D35: Customer Viewer | E35: =F35/G35 -> 0 | F35: =SUM(H35:L35) -> 0 | G35: =SUM(H35:M35) -> 1 | H35: =COUNTIF(Scopes!$M$140,H$3) -> 0 | I35: =COUNTIF(Scopes!$M$140,I$3) -> 0 | J35: =COUNTIF(Scopes!$M$140,J$3) -> 0 | K35: =COUNTIF(Scopes!$M$140,K$3) -> 0 | L35: =COUNTIF(Scopes!$M$140,L$3) -> 0 | M35: =COUNTA(Scopes!$G$140)-SUM(H35:L35) -> 1 | N35: =O35/P35 -> 0 | O35: =SUM(Q35:U35) -> 0 | P35: =SUM(Q35:V35) -> 1 | Q35: =COUNTIF(Scopes!$R$140,Q$3) -> 0 | R35: =COUNTIF(Scopes!$R$140,R$3) -> 0 | S35: =COUNTIF(Scopes!$R$140,S$3) -> 0 | T35: =COUNTIF(Scopes!$R$140,T$3) -> 0 | U35: =COUNTIF(Scopes!$R$140,U$3) -> 0 | V35: =COUNTA(Scopes!$G$140)-SUM(Q35:U35) -> 1
C36: Phân quyền - Permission | D36: Vai trò SGS - SGS roles | E36: =F36/G36 -> 0 | F36: =SUM(H36:L36) -> 0 | G36: =SUM(H36:M36) -> 2 | H36: =COUNTIF(Scopes!$M$141:$M$142,H$3) -> 0 | I36: =COUNTIF(Scopes!$M$141:$M$142,I$3) -> 0 | J36: =COUNTIF(Scopes!$M$141:$M$142,J$3) -> 0 | K36: =COUNTIF(Scopes!$M$141:$M$142,K$3) -> 0 | L36: =COUNTIF(Scopes!$M$141:$M$142,L$3) -> 0 | M36: =COUNTA(Scopes!$G$141:$G$142)-SUM(H36:L36) -> 2 | N36: =O36/P36 -> 0 | O36: =SUM(Q36:U36) -> 0 | P36: =SUM(Q36:V36) -> 2 | Q36: =COUNTIF(Scopes!$R$141:$R$142,Q$3) -> 0 | R36: =COUNTIF(Scopes!$R$141:$R$142,R$3) -> 0 | S36: =COUNTIF(Scopes!$R$141:$R$142,S$3) -> 0 | T36: =COUNTIF(Scopes!$R$141:$R$142,T$3) -> 0 | U36: =COUNTIF(Scopes!$R$141:$R$142,U$3) -> 0 | V36: =COUNTA(Scopes!$G$141:$G$142)-SUM(Q36:U36) -> 2
C37: Bảo mật - Security | D37: Cách ly tenant - Tenant isolation | E37: =F37/G37 -> 0 | F37: =SUM(H37:L37) -> 0 | G37: =SUM(H37:M37) -> 4 | H37: =COUNTIF(Scopes!$M$143:$M$146,H$3) -> 0 | I37: =COUNTIF(Scopes!$M$143:$M$146,I$3) -> 0 | J37: =COUNTIF(Scopes!$M$143:$M$146,J$3) -> 0 | K37: =COUNTIF(Scopes!$M$143:$M$146,K$3) -> 0 | L37: =COUNTIF(Scopes!$M$143:$M$146,L$3) -> 0 | M37: =COUNTA(Scopes!$G$143:$G$146)-SUM(H37:L37) -> 4 | N37: =O37/P37 -> 0 | O37: =SUM(Q37:U37) -> 0 | P37: =SUM(Q37:V37) -> 4 | Q37: =COUNTIF(Scopes!$R$143:$R$146,Q$3) -> 0 | R37: =COUNTIF(Scopes!$R$143:$R$146,R$3) -> 0 | S37: =COUNTIF(Scopes!$R$143:$R$146,S$3) -> 0 | T37: =COUNTIF(Scopes!$R$143:$R$146,T$3) -> 0 | U37: =COUNTIF(Scopes!$R$143:$R$146,U$3) -> 0 | V37: =COUNTA(Scopes!$G$143:$G$146)-SUM(Q37:U37) -> 4
C38: Bảo mật - Security | D38: Dữ liệu nhập - Input | E38: =F38/G38 -> 0 | F38: =SUM(H38:L38) -> 0 | G38: =SUM(H38:M38) -> 1 | H38: =COUNTIF(Scopes!$M$147,H$3) -> 0 | I38: =COUNTIF(Scopes!$M$147,I$3) -> 0 | J38: =COUNTIF(Scopes!$M$147,J$3) -> 0 | K38: =COUNTIF(Scopes!$M$147,K$3) -> 0 | L38: =COUNTIF(Scopes!$M$147,L$3) -> 0 | M38: =COUNTA(Scopes!$G$147)-SUM(H38:L38) -> 1 | N38: =O38/P38 -> 0 | O38: =SUM(Q38:U38) -> 0 | P38: =SUM(Q38:V38) -> 1 | Q38: =COUNTIF(Scopes!$R$147,Q$3) -> 0 | R38: =COUNTIF(Scopes!$R$147,R$3) -> 0 | S38: =COUNTIF(Scopes!$R$147,S$3) -> 0 | T38: =COUNTIF(Scopes!$R$147,T$3) -> 0 | U38: =COUNTIF(Scopes!$R$147,U$3) -> 0 | V38: =COUNTA(Scopes!$G$147)-SUM(Q38:U38) -> 1
C39: Bảo mật - Security | D39: Ghi vết - Audit log | E39: =F39/G39 -> 0 | F39: =SUM(H39:L39) -> 0 | G39: =SUM(H39:M39) -> 1 | H39: =COUNTIF(Scopes!$M$148,H$3) -> 0 | I39: =COUNTIF(Scopes!$M$148,I$3) -> 0 | J39: =COUNTIF(Scopes!$M$148,J$3) -> 0 | K39: =COUNTIF(Scopes!$M$148,K$3) -> 0 | L39: =COUNTIF(Scopes!$M$148,L$3) -> 0 | M39: =COUNTA(Scopes!$G$148)-SUM(H39:L39) -> 1 | N39: =O39/P39 -> 0 | O39: =SUM(Q39:U39) -> 0 | P39: =SUM(Q39:V39) -> 1 | Q39: =COUNTIF(Scopes!$R$148,Q$3) -> 0 | R39: =COUNTIF(Scopes!$R$148,R$3) -> 0 | S39: =COUNTIF(Scopes!$R$148,S$3) -> 0 | T39: =COUNTIF(Scopes!$R$148,T$3) -> 0 | U39: =COUNTIF(Scopes!$R$148,U$3) -> 0 | V39: =COUNTA(Scopes!$G$148)-SUM(Q39:U39) -> 1
C40: Total | E40: =F40/G40 -> 0 | F40: =SUM(H40:L40) -> 0 | G40: =SUM(H40:M40) -> 127 | H40: =SUM(H15:H39) -> 0 | I40: =SUM(I15:I39) -> 0 | J40: =SUM(J15:J39) -> 0 | K40: =SUM(K15:K39) -> 0 | L40: =SUM(L15:L39) -> 0 | M40: =SUM(M15:M39) -> 127 | N40: =O40/P40 -> 0 | O40: =SUM(Q40:U40) -> 0 | P40: =SUM(Q40:V40) -> 127 | Q40: =SUM(Q15:Q39) -> 0 | R40: =SUM(R15:R39) -> 0 | S40: =SUM(S15:S39) -> 0 | T40: =SUM(T15:T39) -> 0 | U40: =SUM(U15:U39) -> 0 | V40: =SUM(V15:V39) -> 127
B41: Users | C41: Điều hướng - Redirect | D41: Vào danh sách - User list | E41: =F41/G41 -> 0 | F41: =SUM(H41:L41) -> 0 | G41: =SUM(H41:M41) -> 2 | H41: =COUNTIF(Users!$M$13:$M$14,H$3) -> 0 | I41: =COUNTIF(Users!$M$13:$M$14,I$3) -> 0 | J41: =COUNTIF(Users!$M$13:$M$14,J$3) -> 0 | K41: =COUNTIF(Users!$M$13:$M$14,K$3) -> 0 | L41: =COUNTIF(Users!$M$13:$M$14,L$3) -> 0 | M41: =COUNTA(Users!$G$13:$G$14)-SUM(H41:L41) -> 2 | N41: =O41/P41 -> 0 | O41: =SUM(Q41:U41) -> 0 | P41: =SUM(Q41:V41) -> 2 | Q41: =COUNTIF(Users!$R$13:$R$14,Q$3) -> 0 | R41: =COUNTIF(Users!$R$13:$R$14,R$3) -> 0 | S41: =COUNTIF(Users!$R$13:$R$14,S$3) -> 0 | T41: =COUNTIF(Users!$R$13:$R$14,T$3) -> 0 | U41: =COUNTIF(Users!$R$13:$R$14,U$3) -> 0 | V41: =COUNTA(Users!$G$13:$G$14)-SUM(Q41:U41) -> 2
...

Sheet Login
B3: Function Name | C3: AUTH-L0001_Đăng nhập | K3: Round | L3: Total | M3: Passed | N3: Failed | O3: Pending | P3: Blocked | Q3: NA | R3: Not execute
B4: Screen Name | C4: Login · Customer Portal | K4: Round 1 | L4: =COUNTA($G$13:$G$112) -> 52 | M4: =COUNTIF($M$13:$M941,M3) -> 0 | N4: =COUNTIF($M$13:$M941,N3) -> 0 | O4: =COUNTIF($M$13:$M941,O3) -> 0 | P4: =COUNTIF($M$13:$M941,P3) -> 0 | Q4: =COUNTIF($M$13:$M941,Q3) -> 0 | R4: =L4-SUM(M4:Q4) -> 52
B5: Creator | C5: Hanna | M5: =M4/$L$4 -> 0 | N5: =N4/$L$4 -> 0 | O5: =O4/$L$4 -> 0 | P5: =P4/$L$4 -> 0 | Q5: =Q4/$L$4 -> 0 | R5: =R4/$L$4 -> 1
B6: Created date | C6: 01/10/2026 | K6: Round 2 | L6: =COUNTA($G$13:$G$112) -> 52 | M6: =COUNTIF($R$13:$R$115,M3) -> 0 | N6: =COUNTIF($R$13:$R$115,N3) -> 0 | O6: =COUNTIF($R$13:$R$115,O3) -> 0 | P6: =COUNTIF($R$13:$R$115,P3) -> 0 | Q6: =COUNTIF($R$13:$R$115,Q3) -> 0 | R6: =L6-SUM(M6:Q6) -> 52
B7: Reference | C7: Figma SGS-DTP-DS · Screens 01 Authentication · Customer / Sign in | M7: =M6/$L$6 -> 0 | N7: =N6/$L$6 -> 0 | O7: =O6/$L$6 -> 0 | P7: =P6/$L$6 -> 0 | Q7: =Q6/$L$6 -> 0 | R7: =R6/$L$6 -> 1
M10: Round 1 | R10: Round 2
B11: Classification | F11: Priority | G11: TVP_ID | H11: Test case name/ Test view point | I11: Pre-condition | J11: Step | K11: Expected result | L11: Dev test | M11: Result | N11: Test person | O11: Test date | P11: Bug_ID | Q11: Remark | R11: Result | S11: Test person | T11: Test date | U11: Bug_ID | V11: Remark | W11: Open question | X11: UC
A12: No. | B12: I | C12: II | D12: III | E12: IV
A13: 1 | B13: Đăng nhập - Login | C13: Điều hướng - Redirect | D13: Vào màn hình | E13: Chưa đăng nhập | F13: High | G13: TC_001 | H13: Kiểm tra đường dẫn vào màn hình đăng nhập | I13: Chưa đăng nhập | J13: 1. Mở {{url.customer}} | K13: - Chuyển sang màn hình Đăng nhập - Hiển thị đủ: logo SGS, tiêu đề Digital Trust Platform, phụ đề Customer Portal | X13: UC-AUTH-001
A14: 2 | E14: Đã đăng nhập | F14: Medium | G14: TC_002 | H14: Kiểm tra khi đã đăng nhập mà mở lại màn đăng nhập | I14: Đã đăng nhập bằng {{user.cust_admin}} | J14: 1. Mở lại {{url.customer}}/login | W14: Chưa rõ: vào thẳng Home hay vẫn hiện màn đăng nhập → Q-L-12 | X14: UC-AUTH-001
A15: 3 | E15: Mở link sâu khi chưa đăng nhập | F15: High | G15: TC_003 | H15: Kiểm tra mở trang nội bộ bằng URL khi chưa đăng nhập | I15: Chưa đăng nhập | J15: 1. Dán URL một trang nội bộ, ví dụ {{url.customer}}/scopes 2. Enter | K15: - Chuyển sang màn hình Đăng nhập, không hiển thị nội dung trang nội bộ | W15: Sau khi đăng nhập có quay lại đúng trang vừa mở không → Q-L-12 | X15: UC-ROL-001
A16: 4 | C16: Hiển thị - Display | D16: Khối bên trái | E16: Thương hiệu | F16: Low | G16: TC_004 | H16: Kiểm tra hiển thị khối thương hiệu bên trái | I16: Chưa đăng nhập | J16: 1. Mở {{url.customer}} 2. Kiểm tra khối bên trái | K16: - Hiển thị hoạ tiết thương hiệu SGS - Tiêu đề: Digital Trust Platform - Phụ đề: Customer Portal | X16: UC-AUTH-001
A17: 5 | D17: Khối bên phải | E17: Logo và tiêu đề | F17: Low | G17: TC_005 | H17: Kiểm tra hiển thị logo và tiêu đề khối đăng nhập | I17: Chưa đăng nhập | J17: 1. Mở {{url.customer}} 2. Kiểm tra phần đầu khối bên phải | K17: - Logo SGS - Tiêu đề: Digital Trust Platform - Phụ đề: Customer Portal | X17: UC-AUTH-001
A18: 6 | E18: Tiêu đề trình duyệt | F18: Low | G18: TC_006 | H18: Kiểm tra tiêu đề tab trình duyệt | I18: Chưa đăng nhập | J18: 1. Mở {{url.customer}} 2. Kiểm tra tiêu đề tab | W18: Chưa có text tiêu đề tab trong thiết kế | X18: UC-AUTH-001
A19: 7 | E19: Màn hình hẹp | F19: Low | G19: TC_007 | H19: Kiểm tra hiển thị ở màn hình hẹp | I19: Chưa đăng nhập | J19: 1. Mở {{url.customer}} 2. Thu nhỏ cửa sổ xuống dưới 768px 3. Kiểm tra bố cục | W19: Thiết kế chưa có bản màn hình hẹp | X19: UC-AUTH-001
A20: 8 | C20: Ngôn ngữ - Language | D20: Bộ chọn ngôn ngữ | E20: Hiển thị mặc định | F20: Medium | G20: TC_008 | H20: Kiểm tra hiển thị mặc định của bộ chọn ngôn ngữ | I20: Chưa đăng nhập | J20: 1. Mở {{url.customer}} 2. Kiểm tra góc trên bên phải | K20: - Hiển thị icon quả địa cầu - Giá trị mặc định: EN - Có mũi tên mở danh sách | W20: Mặc định lấy theo trình duyệt hay cố định EN → Q-L-08 | X20: UC-AUTH-001
A21: 9 | E21: Mở danh sách | F21: Medium | G21: TC_009 | H21: Kiểm tra hiển thị khi mở danh sách ngôn ngữ | I21: Chưa đăng nhập | J21: 1. Mở {{url.customer}} 2. Bấm vào bộ chọn ngôn ngữ | W21: Danh sách ngôn ngữ gồm những gì → Q-L-08 | X21: UC-AUTH-001
A22: 10 | E22: Chọn ngôn ngữ khác | F22: Medium | G22: TC_010 | H22: Kiểm tra khi chọn một ngôn ngữ khác | I22: Chưa đăng nhập | J22: 1. Mở {{url.customer}} 2. Mở danh sách 3. Chọn một ngôn ngữ khác EN | W22: Bản dịch của màn đăng nhập chưa có → Q-L-08 | X22: UC-AUTH-001
A23: 11 | E23: Giữ lựa chọn | F23: Low | G23: TC_011 | H23: Kiểm tra giữ ngôn ngữ đã chọn sau khi tải lại trang | I23: Chưa đăng nhập | J23: 1. Mở {{url.customer}} 2. Chọn ngôn ngữ khác 3. Tải lại trang | W23: Có lưu lựa chọn không → Q-L-08 | X23: UC-AUTH-001
A24: 12 | C24: Email | D24: Hiển thị | E24: Mặc định | F24: High | G24: TC_012 | H24: Kiểm tra hiển thị mặc định của trường Email | I24: Chưa đăng nhập | J24: 1. Mở {{url.customer}} 2. Kiểm tra trường Email | K24: - Nhãn: Email kèm dấu * đỏ - Placeholder: name@company.com - Ô rỗng, không có thông báo lỗi | X24: UC-AUTH-001
A25: 13 | E25: Khi focus | F25: Low | G25: TC_013 | H25: Kiểm tra hiển thị khi đặt con trỏ vào trường Email | I25: Chưa đăng nhập | J25: 1. Mở {{url.customer}} 2. Bấm vào trường Email | K25: - Trường được làm nổi - Placeholder vẫn hiển thị khi chưa gõ | X25: UC-AUTH-001
A26: 14 | D26: Nhập liệu | E26: Nhập hợp lệ | F26: High | G26: TC_014 | H26: Kiểm tra nhập email đúng định dạng | I26: Chưa đăng nhập | J26: 1. Mở {{url.customer}} 2. Nhập {{user.cust_admin}} | K26: - Hiển thị đúng text đã nhập - Không có thông báo lỗi | X26: UC-AUTH-001
A27: 15 | E27: Giới hạn ký tự | F27: Medium | G27: TC_015 | H27: Kiểm tra nhập quá giới hạn ký tự | I27: Chưa đăng nhập | J27: 1. Mở {{url.customer}} 2. Nhập chuỗi dài hơn giới hạn cho phép | W27: Giới hạn ký tự của Email là bao nhiêu → Q-L-10 | X27: UC-AUTH-001
A28: 16 | E28: Ký tự đặc biệt và câu lệnh SQL | F28: High | G28: TC_016 | H28: Kiểm tra nhập ký tự đặc biệt và câu lệnh SQL | I28: Chưa đăng nhập | J28: 1. Mở {{url.customer}} 2. Nhập chuỗi chứa ' OR 1=1 -- và thẻ <script> 3. Bấm Sign in | K28: - Không đăng nhập được - Không có lỗi hệ thống, không lộ thông tin kỹ thuật | W28: Text lỗi hiển thị là gì → Q-L-02 | X28: UC-ROL-001
A29: 17 | E29: Khoảng trắng đầu cuối | F29: Low | G29: TC_017 | H29: Kiểm tra nhập email có khoảng trắng ở đầu và cuối | I29: Chưa đăng nhập | J29: 1. Mở {{url.customer}} 2. Nhập ' {{user.cust_admin}} ' 3. Bấm Sign in | W29: Có tự cắt khoảng trắng không → Q-L-02 | X29: UC-AUTH-001
A30: 18 | E30: Chữ hoa chữ thường | F30: Low | G30: TC_018 | H30: Kiểm tra nhập email viết hoa | I30: Chưa đăng nhập | J30: 1. Mở {{url.customer}} 2. Nhập email đúng nhưng viết hoa toàn bộ 3. Bấm Sign in | W30: Email có phân biệt hoa thường không → Q-L-02 | X30: UC-AUTH-001
A31: 19 | D31: Kiểm tra dữ liệu | E31: Bỏ trống | F31: High | G31: TC_019 | H31: Kiểm tra bỏ trống Email rồi đăng nhập | I31: Chưa đăng nhập | J31: 1. Mở {{url.customer}} 2. Để trống Email 3. Nhập mật khẩu hợp lệ 4. Bấm Sign in | K31: - Không gọi đăng nhập - Hiển thị thông báo lỗi ngay dưới trường Email | W31: Text lỗi nguyên văn → Q-L-01 | X31: UC-AUTH-001
A32: 20 | E32: Sai định dạng | F32: High | G32: TC_020 | H32: Kiểm tra nhập email sai định dạng | I32: Chưa đăng nhập | J32: 1. Mở {{url.customer}} 2. Nhập 'abc@' 3. Nhập mật khẩu hợp lệ 4. Bấm Sign in | K32: - Không gọi đăng nhập - Hiển thị thông báo lỗi ngay dưới trường Email | W32: Text lỗi nguyên văn → Q-L-02 | X32: UC-AUTH-001
A33: 21 | C33: Mật khẩu - Password | D33: Hiển thị | E33: Mặc định | F33: High | G33: TC_021 | H33: Kiểm tra hiển thị mặc định của trường Mật khẩu | I33: Chưa đăng nhập | J33: 1. Mở {{url.customer}} 2. Kiểm tra trường Password | K33: - Nhãn: Password kèm dấu * đỏ - Placeholder: Enter your password - Ô rỗng, không có thông báo lỗi | X33: UC-AUTH-001
A34: 22 | E34: Che ký tự | F34: High | G34: TC_022 | H34: Kiểm tra ký tự mật khẩu được che | I34: Chưa đăng nhập | J34: 1. Mở {{url.customer}} 2. Nhập mật khẩu bất kỳ | K34: - Mọi ký tự hiển thị dạng chấm tròn, không hiện text gốc | X34: UC-AUTH-001
A35: 23 | E35: Nút hiện mật khẩu | F35: Medium | G35: TC_023 | H35: Kiểm tra nút hiện/ẩn mật khẩu | I35: Chưa đăng nhập | J35: 1. Mở {{url.customer}} 2. Kiểm tra bên trong trường Password | W35: Thiết kế không có nút hiện/ẩn mật khẩu — có hay không → Q-L-11 | X35: UC-AUTH-001
A36: 24 | D36: Nhập liệu | E36: Giới hạn ký tự | F36: Medium | G36: TC_024 | H36: Kiểm tra nhập quá giới hạn ký tự | I36: Chưa đăng nhập | J36: 1. Mở {{url.customer}} 2. Nhập chuỗi dài hơn giới hạn cho phép | W36: Giới hạn ký tự của Password là bao nhiêu → Q-L-10 | X36: UC-AUTH-001
A37: 25 | E37: Dán nội dung | F37: Low | G37: TC_025 | H37: Kiểm tra dán mật khẩu từ bộ nhớ tạm | I37: Chưa đăng nhập | J37: 1. Mở {{url.customer}} 2. Dán chuỗi vào trường Password | K37: - Cho phép dán - Ký tự vẫn được che | X37: UC-AUTH-001
A38: 26 | D38: Kiểm tra dữ liệu | E38: Bỏ trống | F38: High | G38: TC_026 | H38: Kiểm tra bỏ trống Mật khẩu rồi đăng nhập | I38: Chưa đăng nhập | J38: 1. Mở {{url.customer}} 2. Nhập Email hợp lệ 3. Để trống Password 4. Bấm Sign in | K38: - Không gọi đăng nhập - Hiển thị thông báo lỗi ngay dưới trường Password | W38: Text lỗi nguyên văn → Q-L-01 | X38: UC-AUTH-001
A39: 27 | E39: Bỏ trống cả hai | F39: High | G39: TC_027 | H39: Kiểm tra bỏ trống cả hai trường rồi đăng nhập | I39: Chưa đăng nhập | J39: 1. Mở {{url.customer}} 2. Để trống cả hai 3. Bấm Sign in | K39: - Không gọi đăng nhập - Hiển thị lỗi ở cả hai trường | W39: Text lỗi nguyên văn → Q-L-01 | X39: UC-AUTH-001
A40: 28 | C40: Ghi nhớ đăng nhập | D40: Checkbox | E40: Mặc định | F40: Medium | G40: TC_028 | H40: Kiểm tra trạng thái mặc định của checkbox | I40: Chưa đăng nhập | J40: 1. Mở {{url.customer}} 2. Kiểm tra checkbox Keep me signed in | K40: - Checkbox ở trạng thái chưa tích - Nhãn: Keep me signed in | X40: UC-AUTH-001
A41: 29 | E41: Tích và bỏ tích | F41: Low | G41: TC_029 | H41: Kiểm tra tích và bỏ tích checkbox | I41: Chưa đăng nhập | J41: 1. Mở {{url.customer}} 2. Tích checkbox 3. Bỏ tích | K41: - Trạng thái đổi theo thao tác | X41: UC-AUTH-001
A42: 30 | D42: Phiên đăng nhập | E42: Có tích | F42: Medium | G42: TC_030 | H42: Kiểm tra thời hạn phiên khi có tích | I42: Chưa đăng nhập | J42: 1. Mở {{url.customer}} 2. Tích checkbox 3. Đăng nhập thành công 4. Đóng trình duyệt rồi mở lại | W42: Thời hạn phiên khi có tích là bao lâu → Q-L-06 | X42: UC-AUTH-001
A43: 31 | E43: Không tích | F43: Medium | G43: TC_031 | H43: Kiểm tra thời hạn phiên khi không tích | I43: Chưa đăng nhập | J43: 1. Mở {{url.customer}} 2. Không tích checkbox 3. Đăng nhập thành công 4. Đóng trình duyệt rồi mở lại | W43: Thời hạn phiên khi không tích là bao lâu → Q-L-06 | X43: UC-AUTH-001
A44: 32 | C44: Đăng nhập - Sign in | D44: Thành công | E44: Đúng cặp email và mật khẩu | F44: High | G44: TC_032 | H44: Kiểm tra đăng nhập với thông tin hợp lệ | I44: Chưa đăng nhập; có tài khoản {{user.cust_admin}} đang hoạt động | J44: 1. Mở {{url.customer}} 2. Nhập {{user.cust_admin}} 3. Nhập mật khẩu đúng 4. Bấm Sign in | K44: - Đăng nhập thành công, không có thông báo lỗi - Rời khỏi màn hình đăng nhập | X44: UC-AUTH-001
...

Sheet Scopes
B3: Function Name | C3: SCP-L0001_Quản lý scope | K3: Round | L3: Total | M3: Passed | N3: Failed | O3: Pending | P3: Blocked | Q3: NA | R3: Not execute
B4: Screen Name | C4: Scopes · Customer Portal | K4: Round 1 | L4: =COUNTA($G$13:$G$148) -> 127 | M4: =COUNTIF($M$13:$M$148,M3) -> 0 | N4: =COUNTIF($M$13:$M$148,N3) -> 0 | O4: =COUNTIF($M$13:$M$148,O3) -> 0 | P4: =COUNTIF($M$13:$M$148,P3) -> 0 | Q4: =COUNTIF($M$13:$M$148,Q3) -> 0 | R4: =L4-SUM(M4:Q4) -> 127
B5: Creator | C5: Hanna | M5: =M4/$L$4 -> 0 | N5: =N4/$L$4 -> 0 | O5: =O4/$L$4 -> 0 | P5: =P4/$L$4 -> 0 | Q5: =Q4/$L$4 -> 0 | R5: =R4/$L$4 -> 1
B6: Created date | C6: 01/10/2026 | K6: Round 2 | L6: =COUNTA($G$13:$G$148) -> 127 | M6: =COUNTIF($R$13:$R$148,M3) -> 0 | N6: =COUNTIF($R$13:$R$148,N3) -> 0 | O6: =COUNTIF($R$13:$R$148,O3) -> 0 | P6: =COUNTIF($R$13:$R$148,P3) -> 0 | Q6: =COUNTIF($R$13:$R$148,Q3) -> 0 | R6: =L6-SUM(M6:Q6) -> 127
B7: Reference | C7: Figma SGS-DTP-DS · Screens 05 Scopes · prototype | M7: =M6/$L$6 -> 0 | N7: =N6/$L$6 -> 0 | O7: =O6/$L$6 -> 0 | P7: =P6/$L$6 -> 0 | Q7: =Q6/$L$6 -> 0 | R7: =R6/$L$6 -> 1
M10: Round 1 | R10: Round 2
B11: Classification | F11: Priority | G11: TVP_ID | H11: Test case name/ Test view point | I11: Pre-condition | J11: Step | K11: Expected result | L11: Dev test | M11: Result | N11: Test person | O11: Test date | P11: Bug_ID | Q11: Remark | R11: Result | S11: Test person | T11: Test date | U11: Bug_ID | V11: Remark | W11: Open question | X11: UC
A12: No. | B12: I | C12: II | D12: III | E12: IV
A13: 13 | B13: Điều hướng - Redirect | C13: Vào danh sách - Scope list | D13: Từ menu | E13: Bấm Scopes ở menu trái | F13: High | G13: Scope_001 | H13: Kiểm tra vào màn Scopes từ menu trái | I13: Đăng nhập account Customer Admin | J13: 1. Bấm mục Scopes ở menu trái | K13: - Chuyển sang màn Scopes - Breadcrumb: Scopes - Mục Scopes ở menu trái được tô nền | X13: UC-SCP-001
A14: 14 | D14: Bằng URL | E14: Đã đăng nhập | F14: Medium | G14: Scope_002 | H14: Kiểm tra mở màn Scopes bằng URL | I14: Đăng nhập account Customer Admin | J14: 1. Mở thẳng vào scopes | K14: - Hiển thị màn Scopes - Mục Scopes ở menu trái được tô nền | X14: UC-SCP-001
A15: 15 | C15: Vào chi tiết - Scope detail | D15: Từ danh sách | E15: Bấm tên scope | F15: High | G15: Scope_003 | H15: Kiểm tra mở chi tiết scope từ danh sách | I15: Đăng nhập account Customer Admin | J15: 1. Vào màn hình Scopes | K15: - Chuyển sang màn chi tiết, đúng dạng URL - Tiêu đề trang đúng định dạng | X15: UC-SCP-002
A16: 16 | D16: Bằng URL | E16: Mã scope hợp lệ | F16: Medium | G16: Scope_004 | H16: Kiểm tra mở chi tiết scope bằng URL | I16: Đăng nhập account Customer Admin | J16: 1. Mở url đúng định dạng | K16: - Hiển thị màn chi tiết của màn hình scope | X16: UC-SCP-002
A17: 17 | E17: Mã scope không tồn tại | F17: Medium | G17: Scope_005 | H17: Kiểm tra mở chi tiết bằng mã scope không tồn tại | I17: Đăng nhập account Customer Admin | J17: 1. Mở url sai định dạng | K17: - Hiển thị lỗi: "This scope doesn’t exist It may have been removed, or it belongs to an organisation you can’t see." | W17: Hiện trang lỗi, thông báo, hay quay về danh sách → Q-S-26 | X17: UC-SCP-002
A18: 18 | B18: Danh sách scope - Scope list | C18: Tiêu đề trang - Title | D18: Hiển thị | E18: Breadcrumb, tiêu đề, mô tả | F18: Medium | G18: Scope_006 | H18: Kiểm tra phần đầu màn Scopes | I18: Đăng nhập account Customer Admin | J18: 1. Mở màn Scopes 2. Kiểm tra phần đầu trang | K18: - Breadcrumb: Scopes - Tiêu đề: Scopes - Mô tả: The parts of [tenant.short] you prepare for a framework: the organisation, a product or a system.J18 | W18: Mô tả dùng tên ngắn (ABC Trading), màn chi tiết dùng tên đầy đủ (ABC Trading Co., Ltd.) → Q-S-02 | X18: UC-SCP-001
C19: Trạng thái rỗng - Empty | D19: Chưa có scope | E19: Customer Admin | F19: Medium | G19: Scope_052 | H19: Kiểm tra màn Scopes khi tenant chưa có scope nào | I19: Đăng nhập Customer Admin của tenant chưa có scope nào | J19: 1. Mở màn Scopes | K19: - Hiển thị thông tin: "Create your first scope A scope is the part of your organisation you want to prepare: the whole organisation, a product, or one system. Link a framework to it to start collecting evidence." | W19: Figma có frame Scopes / Empty, chưa đối chiếu được text → Q-S-10 | X19: UC-SCP-001
A20: 20 | C20: Tạo scope - Create scope | D20: Hiển thị | E20: Nút tạo scope | F20: High | G20: Scope_007 | H20: Kiểm tra hiển thị nút tạo scope | I20: Đăng nhập account Customer Admin | J20: 1. Mở màn Scopes 2. Kiểm tra góc trên bên phải | K20: - Có nút tạo scope ở góc trên bên phải | W20: Nhãn: Figma 'Create scope', prototype '+ Create scope' → Q-S-03 | X20: UC-SCP-003
A21: 21 | D21: Mở hộp thoại | E21: Bấm nút tạo scope | F21: High | G21: Scope_008 | H21: Kiểm tra mở hộp thoại Create scope | I21: Đăng nhập account Customer Admin | J21: 1. Mở màn Scopes 2. Bấm nút tạo scope | K21: - Mở hộp thoại tiêu đề Create scope, có nút đóng × - Có nút Cancel và nút Create scope | X21: UC-SCP-003
A22: 22 | E22: Trạng thái mặc định | F22: High | G22: Scope_009 | H22: Kiểm tra các trường mặc định của hộp thoại Create scope | I22: Đăng nhập account Customer Admin | J22: 1. Mở màn Scopes 2. Mở hộp thoại Create scope 3. Kiểm tra từ trên xuống | K22: - Type * gồm 3 lựa chọn, chưa chọn sẵn lựa chọn nào: Organization — The whole company or one legal entity Product — A product or service you offer System — One information system; can belong to an organisation and a product - Name * rỗng - What is in scope * rỗng - What is out of scope (optional) rỗng, placeholder: e.g. Marketing email tool run by a supplier | X22: UC-SCP-003
A23: 23 | D23: Chọn loại | E23: Chọn System | F23: High | G23: Scope_010 | H23: Kiểm tra các trường hiện thêm khi chọn System | I23: Đăng nhập account Customer Admin | J23: 1. Mở màn Scopes 2. Mở hộp thoại Create scope 3. Chọn System | K23: - Lựa chọn System được đánh dấu - Hiện thêm hai trường: Belongs to organisation (placeholder Choose) và Belongs to product (optional) (mặc định None) | W23: Belongs to organisation không có * cũng không ghi (optional) → Q-S-04 | X23: UC-SCP-003
A24: 24 | E24: Đổi từ System sang loại khác | F24: Medium | G24: Scope_011 | H24: Kiểm tra đổi loại sau khi đã chọn System | I24: Đăng nhập account Customer Admin | J24: 1. Mở màn Scopes 2. Mở hộp thoại, chọn System, chọn một giá trị Belongs to organisation 3. Đổi sang Organization 4. Đổi sang Product | K24: - Ở bước 2 và 3 không còn hai trường Belongs to organisation, Belongs to product (optional) | W24: Giá trị Belongs to đã chọn có bị bỏ khi đổi loại → Q-S-04 | X24: UC-SCP-003
A25: 25 | D25: Danh sách chọn | E25: Belongs to organisation | F25: Medium | G25: Scope_012 | H25: Kiểm tra danh sách chọn của Belongs to organisation | I25: Đăng nhập account Customer Admin | J25: 1. Mở màn Scopes 2. Mở hộp thoại, chọn System 3. Mở danh sách Belongs to organisation | K25: - Chỉ liệt kê scope loại Organization của tenant - Không có scope loại Product, System | X25: UC-SCP-003
A26: 26 | E26: Belongs to product | F26: Medium | G26: Scope_013 | H26: Kiểm tra danh sách chọn của Belongs to product (optional) | I26: Đăng nhập account Customer Admin | J26: 1. Mở màn Scopes 2. Mở hộp thoại, chọn System 3. Mở danh sách Belongs to product (optional) | K26: - Có lựa chọn None - Liệt kê scope loại Product của tenant - Không có scope loại Organization, System | X26: UC-SCP-003
A27: 27 | D27: Không thành công | E27: Không chọn Type | F27: High | G27: Scope_014 | H27: Kiểm tra tạo scope khi chưa chọn Type | I27: Đăng nhập account Customer Admin | J27: 1. Mở màn Scopes 2. Mở hộp thoại 3. Nhập Name, What is in scope; không chọn Type 4. Bấm Create scope | K27: - Không tạo scope, hộp thoại vẫn mở - Hiện lỗi tại Type: "Choose the type of scope." | W27: Text lỗi nguyên văn → Q-S-05 | X27: UC-SCP-003
A28: 28 | E28: Bỏ trống Name | F28: High | G28: Scope_015 | H28: Kiểm tra tạo scope khi bỏ trống Name | I28: Đăng nhập account Customer Admin | J28: 1. Mở màn Scopes 2. Mở hộp thoại 3. Chọn Organization, nhập Name, để trống What is in scope 4. Bấm Create scope | K28: - Không tạo scope, hộp thoại vẫn mở - Hiện lỗi tại Name: "Enter a name." | W28: Text lỗi nguyên văn → Q-S-05 | X28: UC-SCP-003
A29: 29 | E29: Name chỉ có khoảng trắng | F29: Medium | G29: Scope_016 | H29: Kiểm tra tạo scope khi Name chỉ có khoảng trắng | I29: Đăng nhập account Customer Admin | J29: 1. Mở màn Scopes 2. Mở hộp thoại 3. Chọn Organization, nhập Name là ba dấu cách, nhập What is in scope 4. Bấm Create scope | K29: - Không tạo scope, hộp thoại vẫn mở - Hiện lỗi tại Name: "Enter a name." | W29: Khoảng trắng có bị coi là rỗng → Q-S-05 | X29: UC-SCP-003
A30: 30 | E30: Bỏ trống What is in scope | F30: High | G30: Scope_017 | H30: Kiểm tra tạo scope khi bỏ trống What is in scope | I30: Đăng nhập account Customer Admin | J30: 1. Mở màn Scopes 2. Mở hộp thoại 3. Chọn Organization, nhập Name, để trống What is in scope 4. Bấm Create scope | K30: - Không tạo scope, hộp thoại vẫn mở - Hiện lỗi tại What is in scope: "Describe what is in scope." | W30: Text lỗi nguyên văn → Q-S-05 | X30: UC-SCP-003
A31: 31 | E31: What is in scope chỉ có khoảng trắng | F31: Medium | G31: Scope_016 | H31: Kiểm tra tạo scope khi Name chỉ có khoảng trắng | I31: Đăng nhập account Customer Admin | J31: 1. Mở màn Scopes 2. Mở hộp thoại 3. Chọn Organization, nhập Name, nhập What is in scope là ba dấu cách 4. Bấm Create scope | K31: - Không tạo scope, hộp thoại vẫn mở - Hiện lỗi tại What is in scope: "Describe what is in scope." | W31: Trường này bắt buộc hay không → Q-S-04 | X31: UC-SCP-003
A32: 32 | E32: Trùng tên | F32: High | G32: Scope_019 | H32: Kiểm tra tạo scope trùng tên scope đang có | I32: Đăng nhập account Customer Admin | J32: 1. Mở màn Scopes 2. Mở hộp thoại 3. Nhập Name trùng tên [Organization], nhập đủ trường bắt buộc 4. Bấm Create scope | K32: - Không tạo scope, hộp thoại vẫn mở - Hiện lỗi tại Name: "A scope with this name already exists." | W32: Chặn hay cho phép trùng tên; có phân biệt hoa thường → Q-S-05 | X32: UC-SCP-003
E33: Quá giới hạn ký tự | F33: Medium | G33: Scope_020 | H33: Kiểm tra nhập quá giới hạn ký tự | I33: Đăng nhập account Customer Admin | J33: 1. Mở màn Scopes 2. Nhập Name, What is in scope, What is out of scope dài hơn giới hạn | W33: Giới hạn ký tự từng trường → Q-S-05 | X33: UC-SCP-003
E34: Bấm Cancel | F34: Medium | G34: Scope_028 | H34: Kiểm tra huỷ tạo scope bằng Cancel | I34: Đăng nhập account Customer Admin | J34: 1. Mở màn Scopes 2. Mở hộp thoại, chọn loại, nhập Name 3. Bấm Cancel | K34: - Hộp thoại đóng - Bảng không có dòng mới, dòng đếm giữ nguyên | W34: Đang nhập dở có hỏi xác nhận không → Q-S-06 | X34: UC-SCP-003
E35: Bấm × | F35: Low | G35: Scope_029 | H35: Kiểm tra đóng hộp thoại tạo scope bằng nút × | I35: Đăng nhập account Customer Admin | J35: 1. Mở màn Scopes 2. Mở hộp thoại, nhập Name 3. Bấm × | K35: - Hộp thoại đóng, không tạo scope | X35: UC-SCP-003
A36: 33 | E36: Nhấn Esc | F36: Low | G36: Scope_030 | H36: Kiểm tra nhấn Esc khi đang mở hộp thoại tạo scope | I36: Đăng nhập account Customer Admin | J36: 1. Mở màn Scopes 2. Mở hộp thoại, nhập Name 3. Nhấn Esc | K36: - Hộp thoại đóng, không tạo scope | W36: Thiết kế không ghi; prototype đóng hộp thoại ngay → Q-S-06 | X36: UC-SCP-003
A37: 34 | D37: Thành công | E37: Organization — hiện ở danh sách | F37: High | G37: Scope_021 | H37: Kiểm tra thông tin vừa tạo | I37: Đăng nhập account Customer Admin | J37: 1. Mở màn Scopes 2. Bấm nút tạo scope để mở hộp thoại Create scope 3. Chọn Type: Organization 4. Nhập - Name: abc - What is in scope: abc - What is out of scope (optional): abc 5. Bấm Create scope, tạo thành công 6. Kiểm tra dòng vừa tạo trong danh sách | K37: - Hộp thoại đóng, tạo thành công - Danh sách có dòng với Name: abc, nhãn loại Organization - Cột Belongs to: — - Dòng đếm tăng 1 | W37: Danh sách scope có hiển thị What is in scope / What is out of scope không? Yêu cầu của Hanna: kiểm tra cả 4 thông tin trên Danh sách; Figma chỉ có các cột Scope, Belongs to, Frameworks, Users, Evidence coverage → Q-S-28 | X37: UC-SCP-003
A38: 35 | E38: Product — hiện ở danh sách | F38: High | G38: Scope_022 | H38: Kiểm tra thông tin vừa tạo | I38: Đăng nhập account Customer Admin | J38: 1. Mở màn Scopes 2. Bấm nút tạo scope để mở hộp thoại Create scope 3. Chọn Type: Product 4. Nhập - Name: abc - What is in scope: abc - What is out of scope (optional): abc 5. Bấm Create scope, tạo thành công 6. Kiểm tra dòng vừa tạo trong danh sách | K38: - Hộp thoại đóng, tạo thành công - Danh sách có dòng với + Name: abc + Nhãn loại: Product - Cột Belongs to: — - Dòng đếm tăng 1 | W38: Khối Frameworks khi chưa gắn framework hiển thị gì → Q-S-13 | X38: UC-SCP-003
A39: 38 | E39: System — hiện ở danh sách | F39: High | G39: Scope_025 | H39: Kiểm tra scope System vừa tạo hiện ở danh sách | I39: Đăng nhập account Customer Admin | J39: 1. Mở màn Scopes 2. Bấm nút tạo scope để mở hộp thoại Create scope 3. Chọn Type: System 4. Nhập - Name: abc - What is in scope: abc - What is out of scope (optional): abc 5. Chọn - Belongs to organisation: [Organisation] - Belongs to product (optional): [Production] 6. Bấm Create scope, tạo thành công 7. Kiểm tra dòng vừa tạo trong danh sách | K39: - Hộp thoại đóng, tạo thành công - Danh sách có dòng với + Name: abc + Nhãn loại: Product - Cột Belongs to: [Organisation], [Production] - Dòng đếm tăng 1 | W39: Danh sách scope có hiển thị What is in scope / What is out of scope không? Yêu cầu của Hanna: kiểm tra cả 4 thông tin trên Danh sách; Figma chỉ có các cột Scope, Belongs to, Frameworks, Users, Evidence coverage → Q-S-28 | X39: UC-SCP-003
A40: 47 | C40: Thanh công cụ - Toolbar | D40: Dòng đếm | E40: Tổng số scope | F40: Medium | G40: Scope_031 | H40: Kiểm tra dòng đếm số scope | I40: Đăng nhập account Customer Admin | J40: 1. Mở màn Scopes 2. Kiểm tra dòng phía trên bảng, bên trái | K40: - Hiển thị <n> scopes, n bằng tổng số scope trong bảng (cộng mọi trang) | X40: UC-SCP-001
A41: 48 | D41: Tìm kiếm | E41: Hiển thị ô tìm kiếm | F41: Low | G41: Scope_032 | H41: Kiểm tra ô tìm kiếm | I41: Đăng nhập account Customer Admin | J41: 1. Mở màn Scopes 2. Kiểm tra phía trên bảng, bên phải | K41: - Ô tìm kiếm có icon kính lúp, placeholder: Search scopes | X41: UC-SCP-001
A42: 49 | E42: Một phần tên | F42: High | G42: Scope_033 | H42: Kiểm tra tìm theo một phần tên scope | I42: Đăng nhập account Customer Admin | J42: 1. Mở màn Scopes 2. Nhập {{text.partial}} vào ô tìm kiếm | K42: - Bảng chỉ còn các scope có tên chứa {{text.partial}} - Dòng phân trang cập nhật theo số kết quả, ví dụ 1–2 of 2 items | W42: Dòng đếm có đổi theo kết quả không (prototype giữ nguyên tổng) → Q-S-07 | X42: UC-SCP-001
A43: 50 | E43: Chữ hoa | F43: Medium | G43: Scope_034 | H43: Kiểm tra tìm kiếm khi nhập chữ hoa | I43: Đăng nhập account Customer Admin | J43: 1. Mở màn Scopes 2. Nhập {{text.partial_upper}} vào ô tìm kiếm | W43: Có phân biệt hoa thường không (prototype không phân biệt) → Q-S-07 | X43: UC-SCP-001
A44: 51 | E44: Không có kết quả | F44: High | G44: Scope_035 | H44: Kiểm tra tìm kiếm không ra kết quả | I44: Đăng nhập account Customer Admin | J44: 1. Mở màn Scopes 2. Nhập {{text.nomatch}} vào ô tìm kiếm | K44: - Bảng và dòng phân trang ẩn - Thông báo: No results for “{{text.nomatch}}” - Dòng phụ: Try a different search term. | W44: Text lấy từ prototype, Figma chưa có trạng thái này → Q-S-07 | X44: UC-SCP-001
...

Sheet Users
B3: Function Name | C3: USR-L0001_Quản lý người dùng | K3: Round | L3: Total | M3: Passed | N3: Failed | O3: Pending | P3: Blocked | Q3: NA | R3: Not execute
B4: Screen Name | C4: Users · Customer Portal, SGS Portal | K4: Round 1 | L4: =COUNTA($G$13:$G$74) -> 62 | M4: =COUNTIF($M$13:$M$74,M3) -> 0 | N4: =COUNTIF($M$13:$M$74,N3) -> 0 | O4: =COUNTIF($M$13:$M$74,O3) -> 0 | P4: =COUNTIF($M$13:$M$74,P3) -> 0 | Q4: =COUNTIF($M$13:$M$74,Q3) -> 0 | R4: =L4-SUM(M4:Q4) -> 62
B5: Creator | C5: AI (Claude) | M5: =M4/$L$4 -> 0 | N5: =N4/$L$4 -> 0 | O5: =O4/$L$4 -> 0 | P5: =P4/$L$4 -> 0 | Q5: =Q4/$L$4 -> 0 | R5: =R4/$L$4 -> 1
B6: Created date | C6: 05/10/2026 | K6: Round 2 | L6: =COUNTA($G$13:$G$74) -> 62 | M6: =COUNTIF($R$13:$R$74,M3) -> 0 | N6: =COUNTIF($R$13:$R$74,N3) -> 0 | O6: =COUNTIF($R$13:$R$74,O3) -> 0 | P6: =COUNTIF($R$13:$R$74,P3) -> 0 | Q6: =COUNTIF($R$13:$R$74,Q3) -> 0 | R6: =L6-SUM(M6:Q6) -> 62
B7: Reference | C7: UC List v4 (02/10/2026) · USR-01→05, ROL-01, ROL-02 · chưa có Figma trang 02 User & Profile Management: nhãn, bố cục chờ đối chiếu | M7: =M6/$L$6 -> 0 | N7: =N6/$L$6 -> 0 | O7: =O6/$L$6 -> 0 | P7: =P6/$L$6 -> 0 | Q7: =Q6/$L$6 -> 0 | R7: =R6/$L$6 -> 1
M10: Round 1 | R10: Round 2
B11: Classification | F11: Priority | G11: TVP_ID | H11: Test case name/ Test view point | I11: Pre-condition | J11: Step | K11: Expected result | L11: Dev test | M11: Result | N11: Test person | O11: Test date | P11: Bug_ID | Q11: Remark | R11: Result | S11: Test person | T11: Test date | U11: Bug_ID | V11: Remark | W11: Open question | X11: UC
A12: No. | B12: I | C12: II | D12: III | E12: IV
A13: 1 | B13: Điều hướng - Redirect | C13: Vào danh sách - User list | D13: Từ menu | E13: Customer Portal | F13: High | G13: TC_001 | H13: Kiểm tra vào danh sách người dùng từ menu ở Customer Portal | I13: Đăng nhập {{user.cust_admin}}, đang ở màn Home | J13: 1. Bấm Users ở mục Administration của menu trái | K13: - Mở danh sách người dùng của tenant A | W13: Tên mục menu lấy theo prototype của Scopes (Scopes TC_110), chờ Figma trang 02 → Q-U-01 | X13: USR-01
A14: 2 | E14: SGS Portal | F14: High | G14: TC_002 | H14: Kiểm tra vào danh sách người dùng ở SGS Portal | I14: Đăng nhập {{user.sgs_admin}} ở SGS Portal | J14: 1. Mở mục quản lý người dùng ở menu | K14: - Mở danh sách người dùng trong phạm vi của {{user.sgs_admin}} | W14: Lối vào ở SGS Portal chờ Figma trang 02 → Q-U-01 | X14: USR-01
A15: 3 | C15: Vào chi tiết - User detail | D15: Từ danh sách | E15: Mở một người dùng | F15: High | G15: TC_003 | H15: Kiểm tra mở chi tiết người dùng từ danh sách | I15: Đăng nhập {{user.cust_admin}} | J15: 1. Mở danh sách người dùng 2. Mở {{user.cust_user}} trong danh sách | K15: - Mở chi tiết của {{user.cust_user}} | X15: USR-02
A16: 4 | B16: Danh sách người dùng - User list | C16: Phạm vi dữ liệu - Boundary | D16: Customer Admin | E16: Chỉ người dùng của tenant mình | F16: High | G16: TC_004 | H16: Kiểm tra danh sách người dùng của Customer Admin chỉ có tenant mình | I16: Đăng nhập {{user.cust_admin}} (tenant A); tenant B có {{user.tenantB_admin}} | J16: 1. Mở danh sách người dùng 2. Tìm {{user.cust_user}}, {{user.cust_viewer}}, {{user.tenantB_admin}}, {{user.sgs_admin}} | K16: - Có {{user.cust_admin}}, {{user.cust_user}}, {{user.cust_viewer}} - Không có {{user.tenantB_admin}}, không có người dùng SGS nào | X16: USR-01
