Workbook

Sheet Cover
C2: TEST CASE
B3: Project Name | C3: DTP | F3: Creator
B4: Project Code | F4: Reviewer/Approver
B5: Document Code | F5: Issue Date
F6: Version | G6: Version 1.11
B7: Purpose of document
B8: Test environment
B9: Record of change
B10: Effective Date | C10: Version | D10: Change Item | E10: *A,D,M | F10: Change description | G10: Reference
B11: 01/10/2026 | C11: 1.0 | D11: Login, Scopes | E11: A | F11: Tạo mới | G11: UC List v2.1, Figma
B12: 02/10/2026 | C12: 1.1 | D12: Tất cả sheet | E12: M | F12: Một màu, một phông | G12: FB-016, FB-019
B13: 02/10/2026 | C13: 1.1 | D13: Login | E13: M | F13: Sửa vùng đếm tổng kết | G13: FB-019
B14: 05/10/2026 | C14: 1.2 | D14: Users, Profile, Cần xác nhận | E14: A | F14: Tạo mới từ UC List v4; nhãn, bố cục chờ Figma trang 02 | G14: UC List v4
B15: 06/10/2026 | C15: 1.3 | D15: Scopes, Login, Users | E15: M | F15: Pre-condition chỉ ghi trạng thái trước khi vào màn đang test, mở màn là Step 1; đổi Name sang giá trị cụ thể ở các case tạo scope | G15: FB-040
B16: 06/10/2026 | C16: 1.3 | D16: Scopes | E16: A | F16: Thêm Scope_130–132; viết lại Scope_021, 022, 025, 026 kiểm tra đủ Type, Name, In scope, Out of scope; thêm Q-S-28 | G16: FB-041
B17: 07/10/2026 | C17: 1.4 | D17: Scopes | E17: M | F17: Hanna viết lại khu vực Điều hướng và Danh sách scope (No. 1–67) | G17: FB-042 → FB-046
B18: 07/10/2026 | C18: 1.5 | D18: Scopes | E18: M | F18: Viết lại từ Chi tiết scope trở xuống theo cách viết của bản 1.4; thêm case biên cho Evidence coverage, Coverage; đánh lại No. và TVP_ID | G18: FB-042 → FB-048
B19: 07/10/2026 | C19: 1.5 | D19: Tất cả sheet | E19: M | F19: Mọi ô Times New Roman 10; ô bắt đầu bằng dấu - có dấu nháy đơn ở đầu | G19: FB-016, FB-049
B20: 08/10/2026 | C20: 1.6 | D20: Frameworks | E20: A | F20: Thêm sheet Frameworks (118 case; Expected để trống ở case còn câu hỏi Q-F) | G20: UC v4 FWK-01…07
B21: 08/10/2026 | C21: 1.7 | D21: Frameworks | E21: M | F21: Soát lại theo review Opus và các chỗ Hanna sửa: viết lại Total to meet theo công thức, điền Expected cho case kiểm được trên hệ thống, bỏ case trùng, thêm case thiếu | G21: FB-053
... B25: 09/10/2026 | C25: 1.11 | D25: Workspaces | E25: A | F25: Thêm sheet Workspaces: màn danh sách workspace; tạo workspace và Change tier giữ ở sheet Scopes; case còn câu hỏi Q-W để trống Expected | G25: FB-060, FB-061, FB-062
B26: Annotation:
B27: A: Add
B28: D: Delete
B29: M: Modify

Sheet Test_Report
E2: Test Round 1 | N2: Test Round 2 (After fixed bug)
B3: Sheet name | C3: Classification I | D3: Classification II | E3: Executed rate | F3: Executed | G3: Total | H3: Passed | I3: Failed | J3: Pending | K3: Blocked | L3: NA | M3: Not execute | N3: Executed rate | O3: Executed | P3: Total | Q3: Passed | R3: Failed | S3: Pending | T3: Blocked | U3: NA | V3: Not execute
B4: Login | C4: Đăng nhập - Login | D4: Điều hướng - Redirect | E4: =F4/G4 | F4: =SUM(H4:L4) | G4: =SUM(H4:M4) | H4: =COUNTIF('Login'!$M$13:$M$15,H$3) | I4: =COUNTIF('Login'!$M$13:$M$15,I$3) | J4: =COUNTIF('Login'!$M$13:$M$15,J$3) | K4: =COUNTIF('Login'!$M$13:$M$15,K$3) | L4: =COUNTIF('Login'!$M$13:$M$15,L$3) | M4: =COUNTA('Login'!$G$13:$G$15)-SUM(H4:L4) | N4: =O4/P4 | O4: =SUM(Q4:U4) | P4: =SUM(Q4:V4) | Q4: =COUNTIF('Login'!$R$13:$R$15,Q$3) | R4: =COUNTIF('Login'!$R$13:$R$15,R$3) | S4: =COUNTIF('Login'!$R$13:$R$15,S$3) | T4: =COUNTIF('Login'!$R$13:$R$15,T$3) | U4: =COUNTIF('Login'!$R$13:$R$15,U$3) | V4: =COUNTA('Login'!$G$13:$G$15)-SUM(Q4:U4)
C5: Đăng nhập - Login | D5: Hiển thị - Display | E5: =F5/G5 | F5: =SUM(H5:L5) | G5: =SUM(H5:M5) | H5: =COUNTIF('Login'!$M$16:$M$19,H$3) | I5: =COUNTIF('Login'!$M$16:$M$19,I$3) | J5: =COUNTIF('Login'!$M$16:$M$19,J$3) | K5: =COUNTIF('Login'!$M$16:$M$19,K$3) | L5: =COUNTIF('Login'!$M$16:$M$19,L$3) | M5: =COUNTA('Login'!$G$16:$G$19)-SUM(H5:L5) | N5: =O5/P5 | O5: =SUM(Q5:U5) | P5: =SUM(Q5:V5) | Q5: =COUNTIF('Login'!$R$16:$R$19,Q$3) | R5: =COUNTIF('Login'!$R$16:$R$19,R$3) | S5: =COUNTIF('Login'!$R$16:$R$19,S$3) | T5: =COUNTIF('Login'!$R$16:$R$19,T$3) | U5: =COUNTIF('Login'!$R$16:$R$19,U$3) | V5: =COUNTA('Login'!$G$16:$G$19)-SUM(Q5:U5)
C6: Đăng nhập - Login | D6: Ngôn ngữ - Language | E6: =F6/G6 | F6: =SUM(H6:L6) | G6: =SUM(H6:M6) | H6: =COUNTIF('Login'!$M$20:$M$23,H$3) | I6: =COUNTIF('Login'!$M$20:$M$23,I$3) | J6: =COUNTIF('Login'!$M$20:$M$23,J$3) | K6: =COUNTIF('Login'!$M$20:$M$23,K$3) | L6: =COUNTIF('Login'!$M$20:$M$23,L$3) | M6: =COUNTA('Login'!$G$20:$G$23)-SUM(H6:L6) | N6: =O6/P6 | O6: =SUM(Q6:U6) | P6: =SUM(Q6:V6) | Q6: =COUNTIF('Login'!$R$20:$R$23,Q$3) | R6: =COUNTIF('Login'!$R$20:$R$23,R$3) | S6: =COUNTIF('Login'!$R$20:$R$23,S$3) | T6: =COUNTIF('Login'!$R$20:$R$23,T$3) | U6: =COUNTIF('Login'!$R$20:$R$23,U$3) | V6: =COUNTA('Login'!$G$20:$G$23)-SUM(Q6:U6)
C7: Đăng nhập - Login | D7: Email | E7: =F7/G7 | F7: =SUM(H7:L7) | G7: =SUM(H7:M7) | H7: =COUNTIF('Login'!$M$24:$M$32,H$3) | I7: =COUNTIF('Login'!$M$24:$M$32,I$3) | J7: =COUNTIF('Login'!$M$24:$M$32,J$3) | K7: =COUNTIF('Login'!$M$24:$M$32,K$3) | L7: =COUNTIF('Login'!$M$24:$M$32,L$3) | M7: =COUNTA('Login'!$G$24:$G$32)-SUM(H7:L7) | N7: =O7/P7 | O7: =SUM(Q7:U7) | P7: =SUM(Q7:V7) | Q7: =COUNTIF('Login'!$R$24:$R$32,Q$3) | R7: =COUNTIF('Login'!$R$24:$R$32,R$3) | S7: =COUNTIF('Login'!$R$24:$R$32,S$3) | T7: =COUNTIF('Login'!$R$24:$R$32,T$3) | U7: =COUNTIF('Login'!$R$24:$R$32,U$3) | V7: =COUNTA('Login'!$G$24:$G$32)-SUM(Q7:U7)
C8: Đăng nhập - Login | D8: Mật khẩu - Password | E8: =F8/G8 | F8: =SUM(H8:L8) | G8: =SUM(H8:M8) | H8: =COUNTIF('Login'!$M$33:$M$39,H$3) | I8: =COUNTIF('Login'!$M$33:$M$39,I$3) | J8: =COUNTIF('Login'!$M$33:$M$39,J$3) | K8: =COUNTIF('Login'!$M$33:$M$39,K$3) | L8: =COUNTIF('Login'!$M$33:$M$39,L$3) | M8: =COUNTA('Login'!$G$33:$G$39)-SUM(H8:L8) | N8: =O8/P8 | O8: =SUM(Q8:U8) | P8: =SUM(Q8:V8) | Q8: =COUNTIF('Login'!$R$33:$R$39,Q$3) | R8: =COUNTIF('Login'!$R$33:$R$39,R$3) | S8: =COUNTIF('Login'!$R$33:$R$39,S$3) | T8: =COUNTIF('Login'!$R$33:$R$39,T$3) | U8: =COUNTIF('Login'!$R$33:$R$39,U$3) | V8: =COUNTA('Login'!$G$33:$G$39)-SUM(Q8:U8)
C9: Đăng nhập - Login | D9: Ghi nhớ đăng nhập | E9: =F9/G9 | F9: =SUM(H9:L9) | G9: =SUM(H9:M9) | H9: =COUNTIF('Login'!$M$40:$M$43,H$3) | I9: =COUNTIF('Login'!$M$40:$M$43,I$3) | J9: =COUNTIF('Login'!$M$40:$M$43,J$3) | K9: =COUNTIF('Login'!$M$40:$M$43,K$3) | L9: =COUNTIF('Login'!$M$40:$M$43,L$3) | M9: =COUNTA('Login'!$G$40:$G$43)-SUM(H9:L9) | N9: =O9/P9 | O9: =SUM(Q9:U9) | P9: =SUM(Q9:V9) | Q9: =COUNTIF('Login'!$R$40:$R$43,Q$3) | R9: =COUNTIF('Login'!$R$40:$R$43,R$3) | S9: =COUNTIF('Login'!$R$40:$R$43,S$3) | T9: =COUNTIF('Login'!$R$40:$R$43,T$3) | U9: =COUNTIF('Login'!$R$40:$R$43,U$3) | V9: =COUNTA('Login'!$G$40:$G$43)-SUM(Q9:U9)
C10: Đăng nhập - Login | D10: Đăng nhập - Sign in | E10: =F10/G10 | F10: =SUM(H10:L10) | G10: =SUM(H10:M10) | H10: =COUNTIF('Login'!$M$44:$M$53,H$3) | I10: =COUNTIF('Login'!$M$44:$M$53,I$3) | J10: =COUNTIF('Login'!$M$44:$M$53,J$3) | K10: =COUNTIF('Login'!$M$44:$M$53,K$3) | L10: =COUNTIF('Login'!$M$44:$M$53,L$3) | M10: =COUNTA('Login'!$G$44:$G$53)-SUM(H10:L10) | N10: =O10/P10 | O10: =SUM(Q10:U10) | P10: =SUM(Q10:V10) | Q10: =COUNTIF('Login'!$R$44:$R$53,Q$3) | R10: =COUNTIF('Login'!$R$44:$R$53,R$3) | S10: =COUNTIF('Login'!$R$44:$R$53,S$3) | T10: =COUNTIF('Login'!$R$44:$R$53,T$3) | U10: =COUNTIF('Login'!$R$44:$R$53,U$3) | V10: =COUNTA('Login'!$G$44:$G$53)-SUM(Q10:U10)
C11: Đăng nhập - Login | D11: Nút Sign in | E11: =F11/G11 | F11: =SUM(H11:L11) | G11: =SUM(H11:M11) | H11: =COUNTIF('Login'!$M$54:$M$56,H$3) | I11: =COUNTIF('Login'!$M$54:$M$56,I$3) | J11: =COUNTIF('Login'!$M$54:$M$56,J$3) | K11: =COUNTIF('Login'!$M$54:$M$56,K$3) | L11: =COUNTIF('Login'!$M$54:$M$56,L$3) | M11: =COUNTA('Login'!$G$54:$G$56)-SUM(H11:L11) | N11: =O11/P11 | O11: =SUM(Q11:U11) | P11: =SUM(Q11:V11) | Q11: =COUNTIF('Login'!$R$54:$R$56,Q$3) | R11: =COUNTIF('Login'!$R$54:$R$56,R$3) | S11: =COUNTIF('Login'!$R$54:$R$56,S$3) | T11: =COUNTIF('Login'!$R$54:$R$56,T$3) | U11: =COUNTIF('Login'!$R$54:$R$56,U$3) | V11: =COUNTA('Login'!$G$54:$G$56)-SUM(Q11:U11)
C12: Đăng nhập - Login | D12: Hỗ trợ - Support | E12: =F12/G12 | F12: =SUM(H12:L12) | G12: =SUM(H12:M12) | H12: =COUNTIF('Login'!$M$57:$M$59,H$3) | I12: =COUNTIF('Login'!$M$57:$M$59,I$3) | J12: =COUNTIF('Login'!$M$57:$M$59,J$3) | K12: =COUNTIF('Login'!$M$57:$M$59,K$3) | L12: =COUNTIF('Login'!$M$57:$M$59,L$3) | M12: =COUNTA('Login'!$G$57:$G$59)-SUM(H12:L12) | N12: =O12/P12 | O12: =SUM(Q12:U12) | P12: =SUM(Q12:V12) | Q12: =COUNTIF('Login'!$R$57:$R$59,Q$3) | R12: =COUNTIF('Login'!$R$57:$R$59,R$3) | S12: =COUNTIF('Login'!$R$57:$R$59,S$3) | T12: =COUNTIF('Login'!$R$57:$R$59,T$3) | U12: =COUNTIF('Login'!$R$57:$R$59,U$3) | V12: =COUNTA('Login'!$G$57:$G$59)-SUM(Q12:U12)
C13: Đăng nhập - Login | D13: Bảo mật - Security | E13: =F13/G13 | F13: =SUM(H13:L13) | G13: =SUM(H13:M13) | H13: =COUNTIF('Login'!$M$60:$M$64,H$3) | I13: =COUNTIF('Login'!$M$60:$M$64,I$3) | J13: =COUNTIF('Login'!$M$60:$M$64,J$3) | K13: =COUNTIF('Login'!$M$60:$M$64,K$3) | L13: =COUNTIF('Login'!$M$60:$M$64,L$3) | M13: =COUNTA('Login'!$G$60:$G$64)-SUM(H13:L13) | N13: =O13/P13 | O13: =SUM(Q13:U13) | P13: =SUM(Q13:V13) | Q13: =COUNTIF('Login'!$R$60:$R$64,Q$3) | R13: =COUNTIF('Login'!$R$60:$R$64,R$3) | S13: =COUNTIF('Login'!$R$60:$R$64,S$3) | T13: =COUNTIF('Login'!$R$60:$R$64,T$3) | U13: =COUNTIF('Login'!$R$60:$R$64,U$3) | V13: =COUNTA('Login'!$G$60:$G$64)-SUM(Q13:U13)
C14: Total | E14: =F14/G14 | F14: =SUM(H14:L14) | G14: =SUM(H14:M14) | H14: =SUM(H4:H13) | I14: =SUM(I4:I13) | J14: =SUM(J4:J13) | K14: =SUM(K4:K13) | L14: =SUM(L4:L13) | M14: =SUM(M4:M13) | N14: =O14/P14 | O14: =SUM(Q14:U14) | P14: =SUM(Q14:V14) | Q14: =SUM(Q4:Q13) | R14: =SUM(R4:R13) | S14: =SUM(S4:S13) | T14: =SUM(T4:T13) | U14: =SUM(U4:U13) | V14: =SUM(V4:V13)
B15: Scopes | C15: Điều hướng - Redirect | D15: Vào danh sách - Scope list | E15: =F15/G15 | F15: =SUM(H15:L15) | G15: =SUM(H15:M15) | H15: =COUNTIF('Scopes'!$M$13:$M$14,H$3) | I15: =COUNTIF('Scopes'!$M$13:$M$14,I$3) | J15: =COUNTIF('Scopes'!$M$13:$M$14,J$3) | K15: =COUNTIF('Scopes'!$M$13:$M$14,K$3) | L15: =COUNTIF('Scopes'!$M$13:$M$14,L$3) | M15: =COUNTA('Scopes'!$G$13:$G$14)-SUM(H15:L15) | N15: =O15/P15 | O15: =SUM(Q15:U15) | P15: =SUM(Q15:V15) | Q15: =COUNTIF('Scopes'!$R$13:$R$14,Q$3) | R15: =COUNTIF('Scopes'!$R$13:$R$14,R$3) | S15: =COUNTIF('Scopes'!$R$13:$R$14,S$3) | T15: =COUNTIF('Scopes'!$R$13:$R$14,T$3) | U15: =COUNTIF('Scopes'!$R$13:$R$14,U$3) | V15: =COUNTA('Scopes'!$G$13:$G$14)-SUM(Q15:U15)
C16: Điều hướng - Redirect | D16: Vào chi tiết - Scope detail | E16: =F16/G16 | F16: =SUM(H16:L16) | G16: =SUM(H16:M16) | H16: =COUNTIF('Scopes'!$M$15:$M$17,H$3) | I16: =COUNTIF('Scopes'!$M$15:$M$17,I$3) | J16: =COUNTIF('Scopes'!$M$15:$M$17,J$3) | K16: =COUNTIF('Scopes'!$M$15:$M$17,K$3) | L16: =COUNTIF('Scopes'!$M$15:$M$17,L$3) | M16: =COUNTA('Scopes'!$G$15:$G$17)-SUM(H16:L16) | N16: =O16/P16 | O16: =SUM(Q16:U16) | P16: =SUM(Q16:V16) | Q16: =COUNTIF('Scopes'!$R$15:$R$17,Q$3) | R16: =COUNTIF('Scopes'!$R$15:$R$17,R$3) | S16: =COUNTIF('Scopes'!$R$15:$R$17,S$3) | T16: =COUNTIF('Scopes'!$R$15:$R$17,T$3) | U16: =COUNTIF('Scopes'!$R$15:$R$17,U$3) | V16: =COUNTA('Scopes'!$G$15:$G$17)-SUM(Q16:U16)
C17: Danh sách scope - Scope list | D17: Tiêu đề trang - Title | E17: =F17/G17 | F17: =SUM(H17:L17) | G17: =SUM(H17:M17) | H17: =COUNTIF('Scopes'!$M$18:$M$18,H$3) | I17: =COUNTIF('Scopes'!$M$18:$M$18,I$3) | J17: =COUNTIF('Scopes'!$M$18:$M$18,J$3) | K17: =COUNTIF('Scopes'!$M$18:$M$18,K$3) | L17: =COUNTIF('Scopes'!$M$18:$M$18,L$3) | M17: =COUNTA('Scopes'!$G$18:$G$18)-SUM(H17:L17) | N17: =O17/P17 | O17: =SUM(Q17:U17) | P17: =SUM(Q17:V17) | Q17: =COUNTIF('Scopes'!$R$18:$R$18,Q$3) | R17: =COUNTIF('Scopes'!$R$18:$R$18,R$3) | S17: =COUNTIF('Scopes'!$R$18:$R$18,S$3) | T17: =COUNTIF('Scopes'!$R$18:$R$18,T$3) | U17: =COUNTIF('Scopes'!$R$18:$R$18,U$3) | V17: =COUNTA('Scopes'!$G$18:$G$18)-SUM(Q17:U17)
C18: Danh sách scope - Scope list | D18: Trạng thái rỗng - Empty | E18: =F18/G18 | F18: =SUM(H18:L18) | G18: =SUM(H18:M18) | H18: =COUNTIF('Scopes'!$M$19:$M$19,H$3) | I18: =COUNTIF('Scopes'!$M$19:$M$19,I$3) | J18: =COUNTIF('Scopes'!$M$19:$M$19,J$3) | K18: =COUNTIF('Scopes'!$M$19:$M$19,K$3) | L18: =COUNTIF('Scopes'!$M$19:$M$19,L$3) | M18: =COUNTA('Scopes'!$G$19:$G$19)-SUM(H18:L18) | N18: =O18/P18 | O18: =SUM(Q18:U18) | P18: =SUM(Q18:V18) | Q18: =COUNTIF('Scopes'!$R$19:$R$19,Q$3) | R18: =COUNTIF('Scopes'!$R$19:$R$19,R$3) | S18: =COUNTIF('Scopes'!$R$19:$R$19,S$3) | T18: =COUNTIF('Scopes'!$R$19:$R$19,T$3) | U18: =COUNTIF('Scopes'!$R$19:$R$19,U$3) | V18: =COUNTA('Scopes'!$G$19:$G$19)-SUM(Q18:U18)
C19: Danh sách scope - Scope list | D19: Tạo scope - Create scope | E19: =F19/G19 | F19: =SUM(H19:L19) | G19: =SUM(H19:M19) | H19: =COUNTIF('Scopes'!$M$20:$M$39,H$3) | I19: =COUNTIF('Scopes'!$M$20:$M$39,I$3) | J19: =COUNTIF('Scopes'!$M$20:$M$39,J$3) | K19: =COUNTIF('Scopes'!$M$20:$M$39,K$3) | L19: =COUNTIF('Scopes'!$M$20:$M$39,L$3) | M19: =COUNTA('Scopes'!$G$20:$G$39)-SUM(H19:L19) | N19: =O19/P19 | O19: =SUM(Q19:U19) | P19: =SUM(Q19:V19) | Q19: =COUNTIF('Scopes'!$R$20:$R$39,Q$3) | R19: =COUNTIF('Scopes'!$R$20:$R$39,R$3) | S19: =COUNTIF('Scopes'!$R$20:$R$39,S$3) | T19: =COUNTIF('Scopes'!$R$20:$R$39,T$3) | U19: =COUNTIF('Scopes'!$R$20:$R$39,U$3) | V19: =COUNTA('Scopes'!$G$20:$G$39)-SUM(Q19:U19)
C20: Danh sách scope - Scope list | D20: Thanh công cụ - Toolbar | E20: =F20/G20 | F20: =SUM(H20:L20) | G20: =SUM(H20:M20) | H20: =COUNTIF('Scopes'!$M$40:$M$46,H$3) | I20: =COUNTIF('Scopes'!$M$40:$M$46,I$3) | J20: =COUNTIF('Scopes'!$M$40:$M$46,J$3) | K20: =COUNTIF('Scopes'!$M$40:$M$46,K$3) | L20: =COUNTIF('Scopes'!$M$40:$M$46,L$3) | M20: =COUNTA('Scopes'!$G$40:$G$46)-SUM(H20:L20) | N20: =O20/P20 | O20: =SUM(Q20:U20) | P20: =SUM(Q20:V20) | Q20: =COUNTIF('Scopes'!$R$40:$R$46,Q$3) | R20: =COUNTIF('Scopes'!$R$40:$R$46,R$3) | S20: =COUNTIF('Scopes'!$R$40:$R$46,S$3) | T20: =COUNTIF('Scopes'!$R$40:$R$46,T$3) | U20: =COUNTIF('Scopes'!$R$40:$R$46,U$3) | V20: =COUNTA('Scopes'!$G$40:$G$46)-SUM(Q20:U20)
C21: Danh sách scope - Scope list | D21: Bảng danh sách - Table | E21: =F21/G21 | F21: =SUM(H21:L21) | G21: =SUM(H21:M21) | H21: =COUNTIF('Scopes'!$M$47:$M$68,H$3) | I21: =COUNTIF('Scopes'!$M$47:$M$68,I$3) | J21: =COUNTIF('Scopes'!$M$47:$M$68,J$3) | K21: =COUNTIF('Scopes'!$M$47:$M$68,K$3) | L21: =COUNTIF('Scopes'!$M$47:$M$68,L$3) | M21: =COUNTA('Scopes'!$G$47:$G$68)-SUM(H21:L21) | N21: =O21/P21 | O21: =SUM(Q21:U21) | P21: =SUM(Q21:V21) | Q21: =COUNTIF('Scopes'!$R$47:$R$68,Q$3) | R21: =COUNTIF('Scopes'!$R$47:$R$68,R$3) | S21: =COUNTIF('Scopes'!$R$47:$R$68,S$3) | T21: =COUNTIF('Scopes'!$R$47:$R$68,T$3) | U21: =COUNTIF('Scopes'!$R$47:$R$68,U$3) | V21: =COUNTA('Scopes'!$G$47:$G$68)-SUM(Q21:U21)
C22: Danh sách scope - Scope list | D22: Phân trang - Paging | E22: =F22/G22 | F22: =SUM(H22:L22) | G22: =SUM(H22:M22) | H22: =COUNTIF('Scopes'!$M$69:$M$73,H$3) | I22: =COUNTIF('Scopes'!$M$69:$M$73,I$3) | J22: =COUNTIF('Scopes'!$M$69:$M$73,J$3) | K22: =COUNTIF('Scopes'!$M$69:$M$73,K$3) | L22: =COUNTIF('Scopes'!$M$69:$M$73,L$3) | M22: =COUNTA('Scopes'!$G$69:$G$73)-SUM(H22:L22) | N22: =O22/P22 | O22: =SUM(Q22:U22) | P22: =SUM(Q22:V22) | Q22: =COUNTIF('Scopes'!$R$69:$R$73,Q$3) | R22: =COUNTIF('Scopes'!$R$69:$R$73,R$3) | S22: =COUNTIF('Scopes'!$R$69:$R$73,S$3) | T22: =COUNTIF('Scopes'!$R$69:$R$73,T$3) | U22: =COUNTIF('Scopes'!$R$69:$R$73,U$3) | V22: =COUNTA('Scopes'!$G$69:$G$73)-SUM(Q22:U22)
C23: Chi tiết scope - Scope detail | D23: Phần đầu - Header | E23: =F23/G23 | F23: =SUM(H23:L23) | G23: =SUM(H23:M23) | H23: =COUNTIF('Scopes'!$M$74:$M$80,H$3) | I23: =COUNTIF('Scopes'!$M$74:$M$80,I$3) | J23: =COUNTIF('Scopes'!$M$74:$M$80,J$3) | K23: =COUNTIF('Scopes'!$M$74:$M$80,K$3) | L23: =COUNTIF('Scopes'!$M$74:$M$80,L$3) | M23: =COUNTA('Scopes'!$G$74:$G$80)-SUM(H23:L23) | N23: =O23/P23 | O23: =SUM(Q23:U23) | P23: =SUM(Q23:V23) | Q23: =COUNTIF('Scopes'!$R$74:$R$80,Q$3) | R23: =COUNTIF('Scopes'!$R$74:$R$80,R$3) | S23: =COUNTIF('Scopes'!$R$74:$R$80,S$3) | T23: =COUNTIF('Scopes'!$R$74:$R$80,T$3) | U23: =COUNTIF('Scopes'!$R$74:$R$80,U$3) | V23: =COUNTA('Scopes'!$G$74:$G$80)-SUM(Q23:U23)
C24: Chi tiết scope - Scope detail | D24: Điều hướng trong màn - Section nav | E24: =F24/G24 | F24: =SUM(H24:L24) | G24: =SUM(H24:M24) | H24: =COUNTIF('Scopes'!$M$81:$M$82,H$3) | I24: =COUNTIF('Scopes'!$M$81:$M$82,I$3) | J24: =COUNTIF('Scopes'!$M$81:$M$82,J$3) | K24: =COUNTIF('Scopes'!$M$81:$M$82,K$3) | L24: =COUNTIF('Scopes'!$M$81:$M$82,L$3) | M24: =COUNTA('Scopes'!$G$81:$G$82)-SUM(H24:L24) | N24: =O24/P24 | O24: =SUM(Q24:U24) | P24: =SUM(Q24:V24) | Q24: =COUNTIF('Scopes'!$R$81:$R$82,Q$3) | R24: =COUNTIF('Scopes'!$R$81:$R$82,R$3) | S24: =COUNTIF('Scopes'!$R$81:$R$82,S$3) | T24: =COUNTIF('Scopes'!$R$81:$R$82,T$3) | U24: =COUNTIF('Scopes'!$R$81:$R$82,U$3) | V24: =COUNTA('Scopes'!$G$81:$G$82)-SUM(Q24:U24)
C25: Chi tiết scope - Scope detail | D25: Tổng quan - Overview | E25: =F25/G25 | F25: =SUM(H25:L25) | G25: =SUM(H25:M25) | H25: =COUNTIF('Scopes'!$M$83:$M$86,H$3) | I25: =COUNTIF('Scopes'!$M$83:$M$86,I$3) | J25: =COUNTIF('Scopes'!$M$83:$M$86,J$3) | K25: =COUNTIF('Scopes'!$M$83:$M$86,K$3) | L25: =COUNTIF('Scopes'!$M$83:$M$86,L$3) | M25: =COUNTA('Scopes'!$G$83:$G$86)-SUM(H25:L25) | N25: =O25/P25 | O25: =SUM(Q25:U25) | P25: =SUM(Q25:V25) | Q25: =COUNTIF('Scopes'!$R$83:$R$86,Q$3) | R25: =COUNTIF('Scopes'!$R$83:$R$86,R$3) | S25: =COUNTIF('Scopes'!$R$83:$R$86,S$3) | T25: =COUNTIF('Scopes'!$R$83:$R$86,T$3) | U25: =COUNTIF('Scopes'!$R$83:$R$86,U$3) | V25: =COUNTA('Scopes'!$G$83:$G$86)-SUM(Q25:U25)
C26: Chi tiết scope - Scope detail | D26: Sửa scope - Edit scope | E26: =F26/G26 | F26: =SUM(H26:L26) | G26: =SUM(H26:M26) | H26: =COUNTIF('Scopes'!$M$87:$M$95,H$3) | I26: =COUNTIF('Scopes'!$M$87:$M$95,I$3) | J26: =COUNTIF('Scopes'!$M$87:$M$95,J$3) | K26: =COUNTIF('Scopes'!$M$87:$M$95,K$3) | L26: =COUNTIF('Scopes'!$M$87:$M$95,L$3) | M26: =COUNTA('Scopes'!$G$87:$G$95)-SUM(H26:L26) | N26: =O26/P26 | O26: =SUM(Q26:U26) | P26: =SUM(Q26:V26) | Q26: =COUNTIF('Scopes'!$R$87:$R$95,Q$3) | R26: =COUNTIF('Scopes'!$R$87:$R$95,R$3) | S26: =COUNTIF('Scopes'!$R$87:$R$95,S$3) | T26: =COUNTIF('Scopes'!$R$87:$R$95,T$3) | U26: =COUNTIF('Scopes'!$R$87:$R$95,U$3) | V26: =COUNTA('Scopes'!$G$87:$G$95)-SUM(Q26:U26)
C27: Chi tiết scope - Scope detail | D27: Khối Frameworks - Frameworks | E27: =F27/G27 | F27: =SUM(H27:L27) | G27: =SUM(H27:M27) | H27: =COUNTIF('Scopes'!$M$96:$M$107,H$3) | I27: =COUNTIF('Scopes'!$M$96:$M$107,I$3) | J27: =COUNTIF('Scopes'!$M$96:$M$107,J$3) | K27: =COUNTIF('Scopes'!$M$96:$M$107,K$3) | L27: =COUNTIF('Scopes'!$M$96:$M$107,L$3) | M27: =COUNTA('Scopes'!$G$96:$G$107)-SUM(H27:L27) | N27: =O27/P27 | O27: =SUM(Q27:U27) | P27: =SUM(Q27:V27) | Q27: =COUNTIF('Scopes'!$R$96:$R$107,Q$3) | R27: =COUNTIF('Scopes'!$R$96:$R$107,R$3) | S27: =COUNTIF('Scopes'!$R$96:$R$107,S$3) | T27: =COUNTIF('Scopes'!$R$96:$R$107,T$3) | U27: =COUNTIF('Scopes'!$R$96:$R$107,U$3) | V27: =COUNTA('Scopes'!$G$96:$G$107)-SUM(Q27:U27)
C28: Chi tiết scope - Scope detail | D28: Gắn framework - Link framework | E28: =F28/G28 | F28: =SUM(H28:L28) | G28: =SUM(H28:M28) | H28: =COUNTIF('Scopes'!$M$108:$M$119,H$3) | I28: =COUNTIF('Scopes'!$M$108:$M$119,I$3) | J28: =COUNTIF('Scopes'!$M$108:$M$119,J$3) | K28: =COUNTIF('Scopes'!$M$108:$M$119,K$3) | L28: =COUNTIF('Scopes'!$M$108:$M$119,L$3) | M28: =COUNTA('Scopes'!$G$108:$G$119)-SUM(H28:L28) | N28: =O28/P28 | O28: =SUM(Q28:U28) | P28: =SUM(Q28:V28) | Q28: =COUNTIF('Scopes'!$R$108:$R$119,Q$3) | R28: =COUNTIF('Scopes'!$R$108:$R$119,R$3) | S28: =COUNTIF('Scopes'!$R$108:$R$119,S$3) | T28: =COUNTIF('Scopes'!$R$108:$R$119,T$3) | U28: =COUNTIF('Scopes'!$R$108:$R$119,U$3) | V28: =COUNTA('Scopes'!$G$108:$G$119)-SUM(Q28:U28)
C29: Chi tiết scope - Scope detail | D29: Đổi tier - Change tier | E29: =F29/G29 | F29: =SUM(H29:L29) | G29: =SUM(H29:M29) | H29: =COUNTIF('Scopes'!$M$120:$M$125,H$3) | I29: =COUNTIF('Scopes'!$M$120:$M$125,I$3) | J29: =COUNTIF('Scopes'!$M$120:$M$125,J$3) | K29: =COUNTIF('Scopes'!$M$120:$M$125,K$3) | L29: =COUNTIF('Scopes'!$M$120:$M$125,L$3) | M29: =COUNTA('Scopes'!$G$120:$G$125)-SUM(H29:L29) | N29: =O29/P29 | O29: =SUM(Q29:U29) | P29: =SUM(Q29:V29) | Q29: =COUNTIF('Scopes'!$R$120:$R$125,Q$3) | R29: =COUNTIF('Scopes'!$R$120:$R$125,R$3) | S29: =COUNTIF('Scopes'!$R$120:$R$125,S$3) | T29: =COUNTIF('Scopes'!$R$120:$R$125,T$3) | U29: =COUNTIF('Scopes'!$R$120:$R$125,U$3) | V29: =COUNTA('Scopes'!$G$120:$G$125)-SUM(Q29:U29)
C30: Chi tiết scope - Scope detail | D30: Khối Users - Users | E30: =F30/G30 | F30: =SUM(H30:L30) | G30: =SUM(H30:M30) | H30: =COUNTIF('Scopes'!$M$126:$M$128,H$3) | I30: =COUNTIF('Scopes'!$M$126:$M$128,I$3) | J30: =COUNTIF('Scopes'!$M$126:$M$128,J$3) | K30: =COUNTIF('Scopes'!$M$126:$M$128,K$3) | L30: =COUNTIF('Scopes'!$M$126:$M$128,L$3) | M30: =COUNTA('Scopes'!$G$126:$G$128)-SUM(H30:L30) | N30: =O30/P30 | O30: =SUM(Q30:U30) | P30: =SUM(Q30:V30) | Q30: =COUNTIF('Scopes'!$R$126:$R$128,Q$3) | R30: =COUNTIF('Scopes'!$R$126:$R$128,R$3) | S30: =COUNTIF('Scopes'!$R$126:$R$128,S$3) | T30: =COUNTIF('Scopes'!$R$126:$R$128,T$3) | U30: =COUNTIF('Scopes'!$R$126:$R$128,U$3) | V30: =COUNTA('Scopes'!$G$126:$G$128)-SUM(Q30:U30)
C31: Chi tiết scope - Scope detail | D31: Gán người dùng - Assign users | E31: =F31/G31 | F31: =SUM(H31:L31) | G31: =SUM(H31:M31) | H31: =COUNTIF('Scopes'!$M$129:$M$136,H$3) | I31: =COUNTIF('Scopes'!$M$129:$M$136,I$3) | J31: =COUNTIF('Scopes'!$M$129:$M$136,J$3) | K31: =COUNTIF('Scopes'!$M$129:$M$136,K$3) | L31: =COUNTIF('Scopes'!$M$129:$M$136,L$3) | M31: =COUNTA('Scopes'!$G$129:$G$136)-SUM(H31:L31) | N31: =O31/P31 | O31: =SUM(Q31:U31) | P31: =SUM(Q31:V31) | Q31: =COUNTIF('Scopes'!$R$129:$R$136,Q$3) | R31: =COUNTIF('Scopes'!$R$129:$R$136,R$3) | S31: =COUNTIF('Scopes'!$R$129:$R$136,S$3) | T31: =COUNTIF('Scopes'!$R$129:$R$136,T$3) | U31: =COUNTIF('Scopes'!$R$129:$R$136,U$3) | V31: =COUNTA('Scopes'!$G$129:$G$136)-SUM(Q31:U31)
C32: Chi tiết scope - Scope detail | D32: Tổng hợp - Summary | E32: =F32/G32 | F32: =SUM(H32:L32) | G32: =SUM(H32:M32) | H32: =COUNTIF('Scopes'!$M$137:$M$137,H$3) | I32: =COUNTIF('Scopes'!$M$137:$M$137,I$3) | J32: =COUNTIF('Scopes'!$M$137:$M$137,J$3) | K32: =COUNTIF('Scopes'!$M$137:$M$137,K$3) | L32: =COUNTIF('Scopes'!$M$137:$M$137,L$3) | M32: =COUNTA('Scopes'!$G$137:$G$137)-SUM(H32:L32) | N32: =O32/P32 | O32: =SUM(Q32:U32) | P32: =SUM(Q32:V32) | Q32: =COUNTIF('Scopes'!$R$137:$R$137,Q$3) | R32: =COUNTIF('Scopes'!$R$137:$R$137,R$3) | S32: =COUNTIF('Scopes'!$R$137:$R$137,S$3) | T32: =COUNTIF('Scopes'!$R$137:$R$137,T$3) | U32: =COUNTIF('Scopes'!$R$137:$R$137,U$3) | V32: =COUNTA('Scopes'!$G$137:$G$137)-SUM(Q32:U32)
C33: Phân quyền - Permission | D33: Customer User | E33: =F33/G33 | F33: =SUM(H33:L33) | G33: =SUM(H33:M33) | H33: =COUNTIF('Scopes'!$M$138:$M$141,H$3) | I33: =COUNTIF('Scopes'!$M$138:$M$141,I$3) | J33: =COUNTIF('Scopes'!$M$138:$M$141,J$3) | K33: =COUNTIF('Scopes'!$M$138:$M$141,K$3) | L33: =COUNTIF('Scopes'!$M$138:$M$141,L$3) | M33: =COUNTA('Scopes'!$G$138:$G$141)-SUM(H33:L33) | N33: =O33/P33 | O33: =SUM(Q33:U33) | P33: =SUM(Q33:V33) | Q33: =COUNTIF('Scopes'!$R$138:$R$141,Q$3) | R33: =COUNTIF('Scopes'!$R$138:$R$141,R$3) | S33: =COUNTIF('Scopes'!$R$138:$R$141,S$3) | T33: =COUNTIF('Scopes'!$R$138:$R$141,T$3) | U33: =COUNTIF('Scopes'!$R$138:$R$141,U$3) | V33: =COUNTA('Scopes'!$G$138:$G$141)-SUM(Q33:U33)
C34: Phân quyền - Permission | D34: Customer Viewer | E34: =F34/G34 | F34: =SUM(H34:L34) | G34: =SUM(H34:M34) | H34: =COUNTIF('Scopes'!$M$142:$M$142,H$3) | I34: =COUNTIF('Scopes'!$M$142:$M$142,I$3) | J34: =COUNTIF('Scopes'!$M$142:$M$142,J$3) | K34: =COUNTIF('Scopes'!$M$142:$M$142,K$3) | L34: =COUNTIF('Scopes'!$M$142:$M$142,L$3) | M34: =COUNTA('Scopes'!$G$142:$G$142)-SUM(H34:L34) | N34: =O34/P34 | O34: =SUM(Q34:U34) | P34: =SUM(Q34:V34) | Q34: =COUNTIF('Scopes'!$R$142:$R$142,Q$3) | R34: =COUNTIF('Scopes'!$R$142:$R$142,R$3) | S34: =COUNTIF('Scopes'!$R$142:$R$142,S$3) | T34: =COUNTIF('Scopes'!$R$142:$R$142,T$3) | U34: =COUNTIF('Scopes'!$R$142:$R$142,U$3) | V34: =COUNTA('Scopes'!$G$142:$G$142)-SUM(Q34:U34)
C35: Phân quyền - Permission | D35: Vai trò SGS - SGS roles | E35: =F35/G35 | F35: =SUM(H35:L35) | G35: =SUM(H35:M35) | H35: =COUNTIF('Scopes'!$M$143:$M$144,H$3) | I35: =COUNTIF('Scopes'!$M$143:$M$144,I$3) | J35: =COUNTIF('Scopes'!$M$143:$M$144,J$3) | K35: =COUNTIF('Scopes'!$M$143:$M$144,K$3) | L35: =COUNTIF('Scopes'!$M$143:$M$144,L$3) | M35: =COUNTA('Scopes'!$G$143:$G$144)-SUM(H35:L35) | N35: =O35/P35 | O35: =SUM(Q35:U35) | P35: =SUM(Q35:V35) | Q35: =COUNTIF('Scopes'!$R$143:$R$144,Q$3) | R35: =COUNTIF('Scopes'!$R$143:$R$144,R$3) | S35: =COUNTIF('Scopes'!$R$143:$R$144,S$3) | T35: =COUNTIF('Scopes'!$R$143:$R$144,T$3) | U35: =COUNTIF('Scopes'!$R$143:$R$144,U$3) | V35: =COUNTA('Scopes'!$G$143:$G$144)-SUM(Q35:U35)
C36: Bảo mật - Security | D36: Cách ly tenant - Tenant isolation | E36: =F36/G36 | F36: =SUM(H36:L36) | G36: =SUM(H36:M36) | H36: =COUNTIF('Scopes'!$M$145:$M$146,H$3) | I36: =COUNTIF('Scopes'!$M$145:$M$146,I$3) | J36: =COUNTIF('Scopes'!$M$145:$M$146,J$3) | K36: =COUNTIF('Scopes'!$M$145:$M$146,K$3) | L36: =COUNTIF('Scopes'!$M$145:$M$146,L$3) | M36: =COUNTA('Scopes'!$G$145:$G$146)-SUM(H36:L36) | N36: =O36/P36 | O36: =SUM(Q36:U36) | P36: =SUM(Q36:V36) | Q36: =COUNTIF('Scopes'!$R$145:$R$146,Q$3) | R36: =COUNTIF('Scopes'!$R$145:$R$146,R$3) | S36: =COUNTIF('Scopes'!$R$145:$R$146,S$3) | T36: =COUNTIF('Scopes'!$R$145:$R$146,T$3) | U36: =COUNTIF('Scopes'!$R$145:$R$146,U$3) | V36: =COUNTA('Scopes'!$G$145:$G$146)-SUM(Q36:U36)
C37: Bảo mật - Security | D37: Dữ liệu nhập - Input | E37: =F37/G37 | F37: =SUM(H37:L37) | G37: =SUM(H37:M37) | H37: =COUNTIF('Scopes'!$M$147:$M$147,H$3) | I37: =COUNTIF('Scopes'!$M$147:$M$147,I$3) | J37: =COUNTIF('Scopes'!$M$147:$M$147,J$3) | K37: =COUNTIF('Scopes'!$M$147:$M$147,K$3) | L37: =COUNTIF('Scopes'!$M$147:$M$147,L$3) | M37: =COUNTA('Scopes'!$G$147:$G$147)-SUM(H37:L37) | N37: =O37/P37 | O37: =SUM(Q37:U37) | P37: =SUM(Q37:V37) | Q37: =COUNTIF('Scopes'!$R$147:$R$147,Q$3) | R37: =COUNTIF('Scopes'!$R$147:$R$147,R$3) | S37: =COUNTIF('Scopes'!$R$147:$R$147,S$3) | T37: =COUNTIF('Scopes'!$R$147:$R$147,T$3) | U37: =COUNTIF('Scopes'!$R$147:$R$147,U$3) | V37: =COUNTA('Scopes'!$G$147:$G$147)-SUM(Q37:U37)
C38: Bảo mật - Security | D38: Ghi vết - Audit log | E38: =F38/G38 | F38: =SUM(H38:L38) | G38: =SUM(H38:M38) | H38: =COUNTIF('Scopes'!$M$148:$M$148,H$3) | I38: =COUNTIF('Scopes'!$M$148:$M$148,I$3) | J38: =COUNTIF('Scopes'!$M$148:$M$148,J$3) | K38: =COUNTIF('Scopes'!$M$148:$M$148,K$3) | L38: =COUNTIF('Scopes'!$M$148:$M$148,L$3) | M38: =COUNTA('Scopes'!$G$148:$G$148)-SUM(H38:L38) | N38: =O38/P38 | O38: =SUM(Q38:U38) | P38: =SUM(Q38:V38) | Q38: =COUNTIF('Scopes'!$R$148:$R$148,Q$3) | R38: =COUNTIF('Scopes'!$R$148:$R$148,R$3) | S38: =COUNTIF('Scopes'!$R$148:$R$148,S$3) | T38: =COUNTIF('Scopes'!$R$148:$R$148,T$3) | U38: =COUNTIF('Scopes'!$R$148:$R$148,U$3) | V38: =COUNTA('Scopes'!$G$148:$G$148)-SUM(Q38:U38)
C39: Total | E39: =F39/G39 | F39: =SUM(H39:L39) | G39: =SUM(H39:M39) | H39: =SUM(H15:H38) | I39: =SUM(I15:I38) | J39: =SUM(J15:J38) | K39: =SUM(K15:K38) | L39: =SUM(L15:L38) | M39: =SUM(M15:M38) | N39: =O39/P39 | O39: =SUM(Q39:U39) | P39: =SUM(Q39:V39) | Q39: =SUM(Q15:Q38) | R39: =SUM(R15:R38) | S39: =SUM(S15:S38) | T39: =SUM(T15:T38) | U39: =SUM(U15:U38) | V39: =SUM(V15:V38)
B40: Frameworks | C40: Điều hướng - Redirect | D40: Vào danh sách - Framework list | E40: =F40/G40 | F40: =SUM(H40:L40) | G40: =SUM(H40:M40) | H40: =COUNTIF('Frameworks'!$M$13:$M$14,H$3) | I40: =COUNTIF('Frameworks'!$M$13:$M$14,I$3) | J40: =COUNTIF('Frameworks'!$M$13:$M$14,J$3) | K40: =COUNTIF('Frameworks'!$M$13:$M$14,K$3) | L40: =COUNTIF('Frameworks'!$M$13:$M$14,L$3) | M40: =COUNTA('Frameworks'!$G$13:$G$14)-SUM(H40:L40) | N40: =O40/P40 | O40: =SUM(Q40:U40) | P40: =SUM(Q40:V40) | Q40: =COUNTIF('Frameworks'!$R$13:$R$14,Q$3) | R40: =COUNTIF('Frameworks'!$R$13:$R$14,R$3) | S40: =COUNTIF('Frameworks'!$R$13:$R$14,S$3) | T40: =COUNTIF('Frameworks'!$R$13:$R$14,T$3) | U40: =COUNTIF('Frameworks'!$R$13:$R$14,U$3) | V40: =COUNTA('Frameworks'!$G$13:$G$14)-SUM(Q40:U40)
C41: Điều hướng - Redirect | D41: Vào chi tiết - Framework detail | E41: =F41/G41 | F41: =SUM(H41:L41) | G41: =SUM(H41:M41) | H41: =COUNTIF('Frameworks'!$M$15:$M$18,H$3) | I41: =COUNTIF('Frameworks'!$M$15:$M$18,I$3) | J41: =COUNTIF('Frameworks'!$M$15:$M$18,J$3) | K41: =COUNTIF('Frameworks'!$M$15:$M$18,K$3) | L41: =COUNTIF('Frameworks'!$M$15:$M$18,L$3) | M41: =COUNTA('Frameworks'!$G$15:$G$18)-SUM(H41:L41) | N41: =O41/P41 | O41: =SUM(Q41:U41) | P41: =SUM(Q41:V41) | Q41: =COUNTIF('Frameworks'!$R$15:$R$18,Q$3) | R41: =COUNTIF('Frameworks'!$R$15:$R$18,R$3) | S41: =COUNTIF('Frameworks'!$R$15:$R$18,S$3) | T41: =COUNTIF('Frameworks'!$R$15:$R$18,T$3) | U41: =COUNTIF('Frameworks'!$R$15:$R$18,U$3) | V41: =COUNTA('Frameworks'!$G$15:$G$18)-SUM(Q41:U41)
...

Sheet Login
B3: Function Name | C3: AUTH-L0001_Đăng nhập | K3: Round | L3: Total | M3: Passed | N3: Failed | O3: Pending | P3: Blocked | Q3: NA | R3: Not execute
B4: Screen Name | C4: Login · Customer Portal | K4: Round 1 | L4: =COUNTA($G$13:$G$112) -> 52 | M4: =COUNTIF($M$13:$M941,M3) -> 0 | N4: =COUNTIF($M$13:$M941,N3) -> 0 | O4: =COUNTIF($M$13:$M941,O3) -> 0 | P4: =COUNTIF($M$13:$M941,P3) -> 0 | Q4: =COUNTIF($M$13:$M941,Q3) -> 0 | R4: =L4-SUM(M4:Q4) -> 52
B5: Creator | C5: Hanna | M5: =M4/$L$4 -> 0 | N5: =N4/$L$4 -> 0 | O5: =O4/$L$4 -> 0 | P5: =P4/$L$4 -> 0 | Q5: =Q4/$L$4 -> 0 | R5: =R4/$L$4 -> 1
B6: Created date | C6: 01/10/2026 | K6: Round 2 | L6: =COUNTA($G$13:$G$112) -> 52 | M6: =COUNTIF($R$13:$R$115,M3) -> 0 | N6: =COUNTIF($R$13:$R$115,N3) -> 0 | O6: =COUNTIF($R$13:$R$115,O3) -> 0 | P6: =COUNTIF($R$13:$R$115,P3) -> 0 | Q6: =COUNTIF($R$13:$R$115,Q3) -> 0 | R6: =L6-SUM(M6:Q6) -> 52
B7: Reference | C7: Figma SGS-DTP-DS · Screens 01 Authentication · Customer / Sign in | M7: =M6/$L$6 -> 0 | N7: =N6/$L$6 -> 0 | O7: =O6/$L$6 -> 0 | P7: =P6/$L$6 -> 0 | Q7: =Q6/$L$6 -> 0 | R7: =R6/$L$6 -> 1
M10: Round 1 | R10: Round 2
B11: Classification | F11: Priority | G11: TVP_ID | H11: Test case name/ Test view point | I11: Pre-condition | J11: Step | K11: Expected result | L11: Dev test | M11: Result | N11: Test person | O11: Test date | P11: Bug_ID | Q11: Remark | R11: Result | S11: Test person | T11: Test date | U11: Bug_ID | V11: Remark | W11: Open question | X11: UC
A12: No. | B12: I | C12: II | D12: III | E12: IV
A13: 1 | B13: Đăng nhập - Login | C13: Điều hướng - Redirect | D13: Vào màn hình | E13: Chưa đăng nhập | F13: High | G13: TC_001 | H13: Kiểm tra đường dẫn vào màn hình đăng nhập | I13: Chưa đăng nhập | J13: 1. Mở {{url.customer}} | K13: - Chuyển sang màn hình Đăng nhập - Hiển thị đủ: logo SGS, tiêu đề Digital Trust Platform, phụ đề Customer Portal | X13: UC-AUTH-001
A14: 2 | E14: Đã đăng nhập | F14: Medium | G14: TC_002 | H14: Kiểm tra khi đã đăng nhập mà mở lại màn đăng nhập | I14: Đã đăng nhập bằng {{user.cust_admin}} | J14: 1. Mở lại {{url.customer}}/login | W14: Chưa rõ: vào thẳng Home hay vẫn hiện màn đăng nhập → Q-L-12 | X14: UC-AUTH-001
A15: 3 | E15: Mở link sâu khi chưa đăng nhập | F15: High | G15: TC_003 | H15: Kiểm tra mở trang nội bộ bằng URL khi chưa đăng nhập | I15: Chưa đăng nhập | J15: 1. Dán URL một trang nội bộ, ví dụ {{url.customer}}/scopes 2. Enter | K15: - Chuyển sang màn hình Đăng nhập, không hiển thị nội dung trang nội bộ | W15: Sau khi đăng nhập có quay lại đúng trang vừa mở không → Q-L-12 | X15: UC-ROL-001
A16: 4 | C16: Hiển thị - Display | D16: Khối bên trái | E16: Thương hiệu | F16: Low | G16: TC_004 | H16: Kiểm tra hiển thị khối thương hiệu bên trái | I16: Chưa đăng nhập | J16: 1. Mở {{url.customer}} 2. Kiểm tra khối bên trái | K16: - Hiển thị hoạ tiết thương hiệu SGS - Tiêu đề: Digital Trust Platform - Phụ đề: Customer Portal | X16: UC-AUTH-001
A17: 5 | D17: Khối bên phải | E17: Logo và tiêu đề | F17: Low | G17: TC_005 | H17: Kiểm tra hiển thị logo và tiêu đề khối đăng nhập | I17: Chưa đăng nhập | J17: 1. Mở {{url.customer}} 2. Kiểm tra phần đầu khối bên phải | K17: - Logo SGS - Tiêu đề: Digital Trust Platform - Phụ đề: Customer Portal | X17: UC-AUTH-001
A18: 6 | E18: Tiêu đề trình duyệt | F18: Low | G18: TC_006 | H18: Kiểm tra tiêu đề tab trình duyệt | I18: Chưa đăng nhập | J18: 1. Mở {{url.customer}} 2. Kiểm tra tiêu đề tab | W18: Chưa có text tiêu đề tab trong thiết kế | X18: UC-AUTH-001
A19: 7 | E19: Màn hình hẹp | F19: Low | G19: TC_007 | H19: Kiểm tra hiển thị ở màn hình hẹp | I19: Chưa đăng nhập | J19: 1. Mở {{url.customer}} 2. Thu nhỏ cửa sổ xuống dưới 768px 3. Kiểm tra bố cục | W19: Thiết kế chưa có bản màn hình hẹp | X19: UC-AUTH-001
A20: 8 | C20: Ngôn ngữ - Language | D20: Bộ chọn ngôn ngữ | E20: Hiển thị mặc định | F20: Medium | G20: TC_008 | H20: Kiểm tra hiển thị mặc định của bộ chọn ngôn ngữ | I20: Chưa đăng nhập | J20: 1. Mở {{url.customer}} 2. Kiểm tra góc trên bên phải | K20: - Hiển thị icon quả địa cầu - Giá trị mặc định: EN - Có mũi tên mở danh sách | W20: Mặc định lấy theo trình duyệt hay cố định EN → Q-L-08 | X20: UC-AUTH-001
A21: 9 | E21: Mở danh sách | F21: Medium | G21: TC_009 | H21: Kiểm tra hiển thị khi mở danh sách ngôn ngữ | I21: Chưa đăng nhập | J21: 1. Mở {{url.customer}} 2. Bấm vào bộ chọn ngôn ngữ | W21: Danh sách ngôn ngữ gồm những gì → Q-L-08 | X21: UC-AUTH-001
A22: 10 | E22: Chọn ngôn ngữ khác | F22: Medium | G22: TC_010 | H22: Kiểm tra khi chọn một ngôn ngữ khác | I22: Chưa đăng nhập | J22: 1. Mở {{url.customer}} 2. Mở danh sách 3. Chọn một ngôn ngữ khác EN | W22: Bản dịch của màn đăng nhập chưa có → Q-L-08 | X22: UC-AUTH-001
A23: 11 | E23: Giữ lựa chọn | F23: Low | G23: TC_011 | H23: Kiểm tra giữ ngôn ngữ đã chọn sau khi tải lại trang | I23: Chưa đăng nhập | J23: 1. Mở {{url.customer}} 2. Chọn ngôn ngữ khác 3. Tải lại trang | W23: Có lưu lựa chọn không → Q-L-08 | X23: UC-AUTH-001
A24: 12 | C24: Email | D24: Hiển thị | E24: Mặc định | F24: High | G24: TC_012 | H24: Kiểm tra hiển thị mặc định của trường Email | I24: Chưa đăng nhập | J24: 1. Mở {{url.customer}} 2. Kiểm tra trường Email | K24: - Nhãn: Email kèm dấu * đỏ - Placeholder: name@company.com - Ô rỗng, không có thông báo lỗi | X24: UC-AUTH-001
A25: 13 | E25: Khi focus | F25: Low | G25: TC_013 | H25: Kiểm tra hiển thị khi đặt con trỏ vào trường Email | I25: Chưa đăng nhập | J25: 1. Mở {{url.customer}} 2. Bấm vào trường Email | K25: - Trường được làm nổi - Placeholder vẫn hiển thị khi chưa gõ | X25: UC-AUTH-001
A26: 14 | D26: Nhập liệu | E26: Nhập hợp lệ | F26: High | G26: TC_014 | H26: Kiểm tra nhập email đúng định dạng | I26: Chưa đăng nhập | J26: 1. Mở {{url.customer}} 2. Nhập {{user.cust_admin}} | K26: - Hiển thị đúng text đã nhập - Không có thông báo lỗi | X26: UC-AUTH-001
A27: 15 | E27: Giới hạn ký tự | F27: Medium | G27: TC_015 | H27: Kiểm tra nhập quá giới hạn ký tự | I27: Chưa đăng nhập | J27: 1. Mở {{url.customer}} 2. Nhập chuỗi dài hơn giới hạn cho phép | W27: Giới hạn ký tự của Email là bao nhiêu → Q-L-10 | X27: UC-AUTH-001
A28: 16 | E28: Ký tự đặc biệt và câu lệnh SQL | F28: High | G28: TC_016 | H28: Kiểm tra nhập ký tự đặc biệt và câu lệnh SQL | I28: Chưa đăng nhập | J28: 1. Mở {{url.customer}} 2. Nhập chuỗi chứa ' OR 1=1 -- và thẻ <script> 3. Bấm Sign in | K28: - Không đăng nhập được - Không có lỗi hệ thống, không lộ thông tin kỹ thuật | W28: Text lỗi hiển thị là gì → Q-L-02 | X28: UC-ROL-001
A29: 17 | E29: Khoảng trắng đầu cuối | F29: Low | G29: TC_017 | H29: Kiểm tra nhập email có khoảng trắng ở đầu và cuối | I29: Chưa đăng nhập | J29: 1. Mở {{url.customer}} 2. Nhập ' {{user.cust_admin}} ' 3. Bấm Sign in | W29: Có tự cắt khoảng trắng không → Q-L-02 | X29: UC-AUTH-001
A30: 18 | E30: Chữ hoa chữ thường | F30: Low | G30: TC_018 | H30: Kiểm tra nhập email viết hoa | I30: Chưa đăng nhập | J30: 1. Mở {{url.customer}} 2. Nhập email đúng nhưng viết hoa toàn bộ 3. Bấm Sign in | W30: Email có phân biệt hoa thường không → Q-L-02 | X30: UC-AUTH-001
A31: 19 | D31: Kiểm tra dữ liệu | E31: Bỏ trống | F31: High | G31: TC_019 | H31: Kiểm tra bỏ trống Email rồi đăng nhập | I31: Chưa đăng nhập | J31: 1. Mở {{url.customer}} 2. Để trống Email 3. Nhập mật khẩu hợp lệ 4. Bấm Sign in | K31: - Không gọi đăng nhập - Hiển thị thông báo lỗi ngay dưới trường Email | W31: Text lỗi nguyên văn → Q-L-01 | X31: UC-AUTH-001
A32: 20 | E32: Sai định dạng | F32: High | G32: TC_020 | H32: Kiểm tra nhập email sai định dạng | I32: Chưa đăng nhập | J32: 1. Mở {{url.customer}} 2. Nhập 'abc@' 3. Nhập mật khẩu hợp lệ 4. Bấm Sign in | K32: - Không gọi đăng nhập - Hiển thị thông báo lỗi ngay dưới trường Email | W32: Text lỗi nguyên văn → Q-L-02 | X32: UC-AUTH-001
A33: 21 | C33: Mật khẩu - Password | D33: Hiển thị | E33: Mặc định | F33: High | G33: TC_021 | H33: Kiểm tra hiển thị mặc định của trường Mật khẩu | I33: Chưa đăng nhập | J33: 1. Mở {{url.customer}} 2. Kiểm tra trường Password | K33: - Nhãn: Password kèm dấu * đỏ - Placeholder: Enter your password - Ô rỗng, không có thông báo lỗi | X33: UC-AUTH-001
A34: 22 | E34: Che ký tự | F34: High | G34: TC_022 | H34: Kiểm tra ký tự mật khẩu được che | I34: Chưa đăng nhập | J34: 1. Mở {{url.customer}} 2. Nhập mật khẩu bất kỳ | K34: - Mọi ký tự hiển thị dạng chấm tròn, không hiện text gốc | X34: UC-AUTH-001
A35: 23 | E35: Nút hiện mật khẩu | F35: Medium | G35: TC_023 | H35: Kiểm tra nút hiện/ẩn mật khẩu | I35: Chưa đăng nhập | J35: 1. Mở {{url.customer}} 2. Kiểm tra bên trong trường Password | W35: Thiết kế không có nút hiện/ẩn mật khẩu — có hay không → Q-L-11 | X35: UC-AUTH-001
A36: 24 | D36: Nhập liệu | E36: Giới hạn ký tự | F36: Medium | G36: TC_024 | H36: Kiểm tra nhập quá giới hạn ký tự | I36: Chưa đăng nhập | J36: 1. Mở {{url.customer}} 2. Nhập chuỗi dài hơn giới hạn cho phép | W36: Giới hạn ký tự của Password là bao nhiêu → Q-L-10 | X36: UC-AUTH-001
A37: 25 | E37: Dán nội dung | F37: Low | G37: TC_025 | H37: Kiểm tra dán mật khẩu từ bộ nhớ tạm | I37: Chưa đăng nhập | J37: 1. Mở {{url.customer}} 2. Dán chuỗi vào trường Password | K37: - Cho phép dán - Ký tự vẫn được che | X37: UC-AUTH-001
A38: 26 | D38: Kiểm tra dữ liệu | E38: Bỏ trống | F38: High | G38: TC_026 | H38: Kiểm tra bỏ trống Mật khẩu rồi đăng nhập | I38: Chưa đăng nhập | J38: 1. Mở {{url.customer}} 2. Nhập Email hợp lệ 3. Để trống Password 4. Bấm Sign in | K38: - Không gọi đăng nhập - Hiển thị thông báo lỗi ngay dưới trường Password | W38: Text lỗi nguyên văn → Q-L-01 | X38: UC-AUTH-001
A39: 27 | E39: Bỏ trống cả hai | F39: High | G39: TC_027 | H39: Kiểm tra bỏ trống cả hai trường rồi đăng nhập | I39: Chưa đăng nhập | J39: 1. Mở {{url.customer}} 2. Để trống cả hai 3. Bấm Sign in | K39: - Không gọi đăng nhập - Hiển thị lỗi ở cả hai trường | W39: Text lỗi nguyên văn → Q-L-01 | X39: UC-AUTH-001
A40: 28 | C40: Ghi nhớ đăng nhập | D40: Checkbox | E40: Mặc định | F40: Medium | G40: TC_028 | H40: Kiểm tra trạng thái mặc định của checkbox | I40: Chưa đăng nhập | J40: 1. Mở {{url.customer}} 2. Kiểm tra checkbox Keep me signed in | K40: - Checkbox ở trạng thái chưa tích - Nhãn: Keep me signed in | X40: UC-AUTH-001
A41: 29 | E41: Tích và bỏ tích | F41: Low | G41: TC_029 | H41: Kiểm tra tích và bỏ tích checkbox | I41: Chưa đăng nhập | J41: 1. Mở {{url.customer}} 2. Tích checkbox 3. Bỏ tích | K41: - Trạng thái đổi theo thao tác | X41: UC-AUTH-001
A42: 30 | D42: Phiên đăng nhập | E42: Có tích | F42: Medium | G42: TC_030 | H42: Kiểm tra thời hạn phiên khi có tích | I42: Chưa đăng nhập | J42: 1. Mở {{url.customer}} 2. Tích checkbox 3. Đăng nhập thành công 4. Đóng trình duyệt rồi mở lại | W42: Thời hạn phiên khi có tích là bao lâu → Q-L-06 | X42: UC-AUTH-001
A43: 31 | E43: Không tích | F43: Medium | G43: TC_031 | H43: Kiểm tra thời hạn phiên khi không tích | I43: Chưa đăng nhập | J43: 1. Mở {{url.customer}} 2. Không tích checkbox 3. Đăng nhập thành công 4. Đóng trình duyệt rồi mở lại | W43: Thời hạn phiên khi không tích là bao lâu → Q-L-06 | X43: UC-AUTH-001
A44: 32 | C44: Đăng nhập - Sign in | D44: Thành công | E44: Đúng cặp email và mật khẩu | F44: High | G44: TC_032 | H44: Kiểm tra đăng nhập với thông tin hợp lệ | I44: Chưa đăng nhập; có tài khoản {{user.cust_admin}} đang hoạt động | J44: 1. Mở {{url.customer}} 2. Nhập {{user.cust_admin}} 3. Nhập mật khẩu đúng 4. Bấm Sign in | K44: - Đăng nhập thành công, không có thông báo lỗi - Rời khỏi màn hình đăng nhập | X44: UC-AUTH-001
...

Sheet Scopes
B3: Function Name | C3: SCP-L0001_Quản lý scope | K3: Round | L3: Total | M3: Passed | N3: Failed | O3: Pending | P3: Blocked | Q3: NA | R3: Not execute
B4: Screen Name | C4: Scopes · Customer Portal | K4: Round 1 | L4: =COUNTA($G$13:$G$148) -> 136 | M4: =COUNTIF($M$13:$M$148,M3) -> 0 | N4: =COUNTIF($M$13:$M$148,N3) -> 0 | O4: =COUNTIF($M$13:$M$148,O3) -> 0 | P4: =COUNTIF($M$13:$M$148,P3) -> 0 | Q4: =COUNTIF($M$13:$M$148,Q3) -> 0 | R4: =L4-SUM(M4:Q4) -> 136
B5: Creator | C5: Hanna | M5: =M4/$L$4 -> 0 | N5: =N4/$L$4 -> 0 | O5: =O4/$L$4 -> 0 | P5: =P4/$L$4 -> 0 | Q5: =Q4/$L$4 -> 0 | R5: =R4/$L$4 -> 1
B6: Created date | C6: 01/10/2026 | K6: Round 2 | L6: =COUNTA($G$13:$G$148) -> 136 | M6: =COUNTIF($R$13:$R$148,M3) -> 0 | N6: =COUNTIF($R$13:$R$148,N3) -> 0 | O6: =COUNTIF($R$13:$R$148,O3) -> 0 | P6: =COUNTIF($R$13:$R$148,P3) -> 0 | Q6: =COUNTIF($R$13:$R$148,Q3) -> 0 | R6: =L6-SUM(M6:Q6) -> 136
B7: Reference | C7: Figma SGS-DTP-DS · Screens 05 Scopes · prototype | M7: =M6/$L$6 -> 0 | N7: =N6/$L$6 -> 0 | O7: =O6/$L$6 -> 0 | P7: =P6/$L$6 -> 0 | Q7: =Q6/$L$6 -> 0 | R7: =R6/$L$6 -> 1
M10: Round 1 | R10: Round 2
B11: Classification | F11: Priority | G11: TVP_ID | H11: Test case name/ Test view point | I11: Pre-condition | J11: Step | K11: Expected result | L11: Dev test | M11: Result | N11: Test person | O11: Test date | P11: Bug_ID | Q11: Remark | R11: Result | S11: Test person | T11: Test date | U11: Bug_ID | V11: Remark | W11: Open question | X11: UC
A12: No. | B12: I | C12: II | D12: III | E12: IV
A13: 1 | B13: Điều hướng - Redirect | C13: Vào danh sách - Scope list | D13: Từ menu | E13: Bấm Scopes ở menu trái | F13: High | G13: Scope_001 | H13: Kiểm tra vào màn Scopes từ menu trái | I13: Đăng nhập account Customer Admin | J13: 1. Bấm mục Scopes ở menu trái | K13: - Chuyển sang màn Scopes - Breadcrumb: Scopes - Mục Scopes ở menu trái được tô nền | X13: UC-SCP-001
A14: 2 | D14: Bằng URL | E14: Đã đăng nhập | F14: Medium | G14: Scope_002 | H14: Kiểm tra mở màn Scopes bằng URL | I14: Đăng nhập account Customer Admin | J14: 1. Mở thẳng vào scopes | K14: - Hiển thị màn Scopes - Mục Scopes ở menu trái được tô nền | X14: UC-SCP-001
A15: 3 | C15: Vào chi tiết - Scope detail | D15: Từ danh sách | E15: Bấm tên scope | F15: High | G15: Scope_003 | H15: Kiểm tra mở chi tiết scope từ danh sách | I15: Đăng nhập account Customer Admin | J15: 1. Vào màn hình Scopes | K15: - Chuyển sang màn chi tiết, đúng dạng URL - Tiêu đề trang đúng định dạng | X15: UC-SCP-002
A16: 4 | D16: Bằng URL | E16: Mã scope hợp lệ | F16: Medium | G16: Scope_004 | H16: Kiểm tra mở chi tiết scope bằng URL | I16: Đăng nhập account Customer Admin | J16: 1. Mở url đúng định dạng | K16: - Hiển thị màn chi tiết của màn hình scope | X16: UC-SCP-002
A17: 5 | E17: Mã scope không tồn tại | F17: Medium | G17: Scope_005 | H17: Kiểm tra mở chi tiết bằng mã scope không tồn tại | I17: Đăng nhập account Customer Admin | J17: 1. Mở url sai định dạng | K17: - Hiển thị lỗi: "This scope doesn’t exist It may have been removed, or it belongs to an organisation you can’t see." | W17: Hiện trang lỗi, thông báo, hay quay về danh sách → Q-S-26 | X17: UC-SCP-002
A18: 6 | B18: Danh sách scope - Scope list | C18: Tiêu đề trang - Title | D18: Hiển thị | E18: Breadcrumb, tiêu đề, mô tả | F18: Medium | G18: Scope_006 | H18: Kiểm tra phần đầu màn Scopes | I18: Đăng nhập account Customer Admin | J18: 1. Mở màn Scopes 2. Kiểm tra phần đầu trang | K18: - Breadcrumb: Scopes - Tiêu đề: Scopes - Mô tả: The parts of [tenant.short] you prepare for a framework: the organisation, a product or a system. | W18: Mô tả dùng tên ngắn (ABC Trading), màn chi tiết dùng tên đầy đủ (ABC Trading Co., Ltd.) → Q-S-02 | X18: UC-SCP-001
A19: 7 | C19: Trạng thái rỗng - Empty | D19: Chưa có scope | E19: Customer Admin | F19: Medium | G19: Scope_007 | H19: Kiểm tra màn Scopes khi tenant chưa có scope nào | I19: Đăng nhập Customer Admin của tenant chưa có scope nào | J19: 1. Mở màn Scopes | K19: - Hiển thị thông tin: "Create your first scope A scope is the part of your organisation you want to prepare: the whole organisation, a product, or one system. Link a framework to it to start collecting evidence." | W19: Figma có frame Scopes / Empty, chưa đối chiếu được text → Q-S-10 | X19: UC-SCP-001
A20: 8 | C20: Tạo scope - Create scope | D20: Hiển thị | E20: Nút tạo scope | F20: High | G20: Scope_008 | H20: Kiểm tra hiển thị nút tạo scope | I20: Đăng nhập account Customer Admin | J20: 1. Mở màn Scopes 2. Kiểm tra góc trên bên phải | K20: - Có nút tạo scope ở góc trên bên phải | W20: Nhãn: Figma 'Create scope', prototype '+ Create scope' → Q-S-03 | X20: UC-SCP-003
A21: 9 | D21: Mở hộp thoại | E21: Bấm nút tạo scope | F21: High | G21: Scope_009 | H21: Kiểm tra mở hộp thoại Create scope | I21: Đăng nhập account Customer Admin | J21: 1. Mở màn Scopes 2. Bấm nút tạo scope | K21: - Mở hộp thoại tiêu đề Create scope, có nút đóng × - Có nút Cancel và nút Create scope | X21: UC-SCP-003
A22: 10 | E22: Trạng thái mặc định | F22: High | G22: Scope_010 | H22: Kiểm tra các trường mặc định của hộp thoại Create scope | I22: Đăng nhập account Customer Admin | J22: 1. Mở màn Scopes 2. Mở hộp thoại Create scope 3. Kiểm tra từ trên xuống | K22: - Type * gồm 3 lựa chọn, chưa chọn sẵn lựa chọn nào: Organization — The whole company or one legal entity Product — A product or service you offer System — One information system; can belong to an organisation and a product - Name * rỗng - What is in scope * rỗng - What is out of scope (optional) rỗng, placeholder: e.g. Marketing email tool run by a supplier | X22: UC-SCP-003
A23: 11 | D23: Chọn loại | E23: Chọn System | F23: High | G23: Scope_011 | H23: Kiểm tra các trường hiện thêm khi chọn System | I23: Đăng nhập account Customer Admin | J23: 1. Mở màn Scopes 2. Mở hộp thoại Create scope 3. Chọn System | K23: - Lựa chọn System được đánh dấu - Hiện thêm hai trường: Belongs to organisation (placeholder Choose) và Belongs to product (optional) (mặc định None) | W23: Belongs to organisation không có * cũng không ghi (optional) → Q-S-04 | X23: UC-SCP-003
A24: 12 | E24: Đổi từ System sang loại khác | F24: Medium | G24: Scope_012 | H24: Kiểm tra đổi loại sau khi đã chọn System | I24: Đăng nhập account Customer Admin | J24: 1. Mở màn Scopes 2. Mở hộp thoại, chọn System, chọn một giá trị Belongs to organisation 3. Đổi sang Organization 4. Đổi sang Product | K24: - Ở bước 2 và 3 không còn hai trường Belongs to organisation, Belongs to product (optional) | W24: Giá trị Belongs to đã chọn có bị bỏ khi đổi loại → Q-S-04 | X24: UC-SCP-003
A25: 13 | D25: Danh sách chọn | E25: Belongs to organisation | F25: Medium | G25: Scope_013 | H25: Kiểm tra danh sách chọn của Belongs to organisation | I25: Đăng nhập account Customer Admin | J25: 1. Mở màn Scopes 2. Mở hộp thoại, chọn System 3. Mở danh sách Belongs to organisation | K25: - Chỉ liệt kê scope loại Organization của tenant - Không có scope loại Product, System | X25: UC-SCP-003
A26: 14 | E26: Belongs to product | F26: Medium | G26: Scope_014 | H26: Kiểm tra danh sách chọn của Belongs to product (optional) | I26: Đăng nhập account Customer Admin | J26: 1. Mở màn Scopes 2. Mở hộp thoại, chọn System 3. Mở danh sách Belongs to product (optional) | K26: - Có lựa chọn None - Liệt kê scope loại Product của tenant - Không có scope loại Organization, System | X26: UC-SCP-003
A27: 15 | D27: Không thành công | E27: Không chọn Type | F27: High | G27: Scope_015 | H27: Kiểm tra tạo scope khi chưa chọn Type | I27: Đăng nhập account Customer Admin | J27: 1. Mở màn Scopes 2. Mở hộp thoại 3. Nhập Name, What is in scope; không chọn Type 4. Bấm Create scope | K27: - Không tạo scope, hộp thoại vẫn mở - Hiện lỗi tại Type: "Choose the type of scope." | W27: Text lỗi nguyên văn → Q-S-05 | X27: UC-SCP-003
A28: 16 | E28: Bỏ trống Name | F28: High | G28: Scope_016 | H28: Kiểm tra tạo scope khi bỏ trống Name | I28: Đăng nhập account Customer Admin | J28: 1. Mở màn Scopes 2. Mở hộp thoại 3. Chọn Organization, nhập What is in scope, để trống Name 4. Bấm Create scope | K28: - Không tạo scope, hộp thoại vẫn mở - Hiện lỗi tại Name: "Enter a name." | W28: Text lỗi nguyên văn → Q-S-05 | X28: UC-SCP-003
A29: 17 | E29: Name chỉ có khoảng trắng | F29: Medium | G29: Scope_017 | H29: Kiểm tra tạo scope khi Name chỉ có khoảng trắng | I29: Đăng nhập account Customer Admin | J29: 1. Mở màn Scopes 2. Mở hộp thoại 3. Chọn Organization, nhập Name là ba dấu cách, nhập What is in scope 4. Bấm Create scope | K29: - Không tạo scope, hộp thoại vẫn mở - Hiện lỗi tại Name: "Enter a name." | W29: Khoảng trắng có bị coi là rỗng → Q-S-05 | X29: UC-SCP-003
A30: 18 | E30: Bỏ trống What is in scope | F30: High | G30: Scope_018 | H30: Kiểm tra tạo scope khi bỏ trống What is in scope | I30: Đăng nhập account Customer Admin | J30: 1. Mở màn Scopes 2. Mở hộp thoại 3. Chọn Organization, nhập Name, để trống What is in scope 4. Bấm Create scope | K30: - Không tạo scope, hộp thoại vẫn mở - Hiện lỗi tại What is in scope: "Describe what is in scope." | W30: Text lỗi nguyên văn → Q-S-05 | X30: UC-SCP-003
A31: 19 | E31: What is in scope chỉ có khoảng trắng | F31: Medium | G31: Scope_019 | H31: Kiểm tra tạo scope khi What is in scope chỉ có khoảng trắng | I31: Đăng nhập account Customer Admin | J31: 1. Mở màn Scopes 2. Mở hộp thoại 3. Chọn Organization, nhập Name, nhập What is in scope là ba dấu cách 4. Bấm Create scope | K31: - Không tạo scope, hộp thoại vẫn mở - Hiện lỗi tại What is in scope: "Describe what is in scope." | W31: Khoảng trắng có bị coi là rỗng → Q-S-05 | X31: UC-SCP-003
A32: 20 | E32: Trùng tên | F32: High | G32: Scope_020 | H32: Kiểm tra tạo scope trùng tên scope đang có | I32: Đăng nhập account Customer Admin | J32: 1. Mở màn Scopes 2. Mở hộp thoại 3. Nhập Name trùng tên [Organization], nhập đủ trường bắt buộc 4. Bấm Create scope | K32: - Không tạo scope, hộp thoại vẫn mở - Hiện lỗi tại Name: "A scope with this name already exists." | W32: Chặn hay cho phép trùng tên; có phân biệt hoa thường → Q-S-05 | X32: UC-SCP-003
A33: 21 | E33: Quá giới hạn ký tự | F33: Medium | G33: Scope_021 | H33: Kiểm tra nhập quá giới hạn ký tự | I33: Đăng nhập account Customer Admin | J33: 1. Mở màn Scopes 2. Nhập Name, What is in scope, What is out of scope dài hơn giới hạn | W33: Giới hạn ký tự từng trường → Q-S-05 | X33: UC-SCP-003
A34: 22 | E34: Bấm Cancel | F34: Medium | G34: Scope_022 | H34: Kiểm tra huỷ tạo scope bằng Cancel | I34: Đăng nhập account Customer Admin | J34: 1. Mở màn Scopes 2. Mở hộp thoại, chọn loại, nhập Name 3. Bấm Cancel | K34: - Hộp thoại đóng - Bảng không có dòng mới, dòng đếm giữ nguyên | W34: Đang nhập dở có hỏi xác nhận không → Q-S-06 | X34: UC-SCP-003
A35: 23 | E35: Bấm × | F35: Low | G35: Scope_023 | H35: Kiểm tra đóng hộp thoại tạo scope bằng nút × | I35: Đăng nhập account Customer Admin | J35: 1. Mở màn Scopes 2. Mở hộp thoại, nhập Name 3. Bấm × | K35: - Hộp thoại đóng, không tạo scope | X35: UC-SCP-003
A36: 24 | E36: Nhấn Esc | F36: Low | G36: Scope_024 | H36: Kiểm tra nhấn Esc khi đang mở hộp thoại tạo scope | I36: Đăng nhập account Customer Admin | J36: 1. Mở màn Scopes 2. Mở hộp thoại, nhập Name 3. Nhấn Esc | K36: - Hộp thoại đóng, không tạo scope | W36: Thiết kế không ghi; prototype đóng hộp thoại ngay → Q-S-06 | X36: UC-SCP-003
A37: 25 | D37: Thành công | E37: Organization — hiện ở danh sách | F37: High | G37: Scope_025 | H37: Kiểm tra thông tin vừa tạo | I37: Đăng nhập account Customer Admin | J37: 1. Mở màn Scopes 2. Bấm nút tạo scope để mở hộp thoại Create scope 3. Chọn Type: Organization 4. Nhập - Name: abc - What is in scope: abc - What is out of scope (optional): abc 5. Bấm Create scope, tạo thành công 6. Kiểm tra dòng vừa tạo trong danh sách | K37: - Hộp thoại đóng, tạo thành công - Danh sách có dòng với Name: abc, nhãn loại Organization - Cột Belongs to: — - Dòng đếm tăng 1 | W37: Danh sách scope có hiển thị What is in scope / What is out of scope không? Yêu cầu của Hanna: kiểm tra cả 4 thông tin trên Danh sách; Figma chỉ có các cột Scope, Belongs to, Frameworks, Users, Evidence coverage → Q-S-28 | X37: UC-SCP-003
A38: 26 | E38: Product — hiện ở danh sách | F38: High | G38: Scope_026 | H38: Kiểm tra thông tin vừa tạo | I38: Đăng nhập account Customer Admin | J38: 1. Mở màn Scopes 2. Bấm nút tạo scope để mở hộp thoại Create scope 3. Chọn Type: Product 4. Nhập - Name: abc - What is in scope: abc - What is out of scope (optional): abc 5. Bấm Create scope, tạo thành công 6. Kiểm tra dòng vừa tạo trong danh sách | K38: - Hộp thoại đóng, tạo thành công - Danh sách có dòng với + Name: abc + Nhãn loại: Product - Cột Belongs to: — - Dòng đếm tăng 1 | W38: Danh sách scope có hiển thị What is in scope / What is out of scope không? Yêu cầu của Hanna: kiểm tra cả 4 thông tin trên Danh sách; Figma chỉ có các cột Scope, Belongs to, Frameworks, Users, Evidence coverage → Q-S-28 | X38: UC-SCP-003
A39: 27 | E39: System — hiện ở danh sách | F39: High | G39: Scope_027 | H39: Kiểm tra scope System vừa tạo hiện ở danh sách | I39: Đăng nhập account Customer Admin | J39: 1. Mở màn Scopes 2. Bấm nút tạo scope để mở hộp thoại Create scope 3. Chọn Type: System 4. Nhập - Name: abc - What is in scope: abc - What is out of scope (optional): abc 5. Chọn - Belongs to organisation: [Organization] - Belongs to product (optional): [Product] 6. Bấm Create scope, tạo thành công 7. Kiểm tra dòng vừa tạo trong danh sách | K39: - Hộp thoại đóng, tạo thành công - Danh sách có dòng với + Name: abc + Nhãn loại: System - Cột Belongs to: [Organization], [Product] - Dòng đếm tăng 1 | W39: Danh sách scope có hiển thị What is in scope / What is out of scope không? Yêu cầu của Hanna: kiểm tra cả 4 thông tin trên Danh sách; Figma chỉ có các cột Scope, Belongs to, Frameworks, Users, Evidence coverage → Q-S-28 | X39: UC-SCP-003
A40: 28 | C40: Thanh công cụ - Toolbar | D40: Dòng đếm | E40: Tổng số scope | F40: Medium | G40: Scope_028 | H40: Kiểm tra dòng đếm số scope | I40: Đăng nhập account Customer Admin | J40: 1. Mở màn Scopes 2. Kiểm tra dòng phía trên bảng, bên trái | K40: - Hiển thị <n> scopes, n bằng tổng số scope trong bảng (cộng mọi trang) | X40: UC-SCP-001
A41: 29 | D41: Tìm kiếm | E41: Hiển thị ô tìm kiếm | F41: Low | G41: Scope_029 | H41: Kiểm tra ô tìm kiếm | I41: Đăng nhập account Customer Admin | J41: 1. Mở màn Scopes 2. Kiểm tra phía trên bảng, bên phải | K41: - Ô tìm kiếm có icon kính lúp, placeholder: Search scopes | X41: UC-SCP-001
A42: 30 | E42: Một phần tên | F42: High | G42: Scope_030 | H42: Kiểm tra tìm theo một phần tên scope | I42: Đăng nhập account Customer Admin | J42: 1. Mở màn Scopes 2. Nhập [từ khóa] là một phần tên scope vào ô tìm kiếm | K42: - Bảng chỉ còn các scope có tên chứa [từ khóa] - Dòng phân trang cập nhật theo số kết quả, ví dụ 1–2 of 2 items | W42: Dòng đếm có đổi theo kết quả không (prototype giữ nguyên tổng) → Q-S-07 | X42: UC-SCP-001
A43: 31 | E43: Chữ hoa | F43: Medium | G43: Scope_031 | H43: Kiểm tra tìm kiếm khi nhập chữ hoa | I43: Đăng nhập account Customer Admin | J43: 1. Mở màn Scopes 2. Nhập [từ khóa] viết hoa vào ô tìm kiếm | K43: - Hệ thống hiển thị data đúng định dạng, không phân biệt chữ hoa hay không | W43: Có phân biệt hoa thường không (prototype không phân biệt) → Q-S-07 | X43: UC-SCP-001
A44: 32 | E44: Không có kết quả | F44: High | G44: Scope_032 | H44: Kiểm tra tìm kiếm không ra kết quả | I44: Đăng nhập account Customer Admin | J44: 1. Mở màn Scopes 2. Nhập [từ khóa] không khớp tên scope nào vào ô tìm kiếm | K44: - Bảng và dòng phân trang ẩn - Thông báo: No results for “[từ khóa]” - Dòng phụ: Try a different search term. | W44: Text lấy từ prototype, Figma chưa có trạng thái này → Q-S-07 | X44: UC-SCP-001
...

Sheet Frameworks
B3: Function Name | C3: FWK-L0001_Quản lý framework | K3: Round | L3: Total | M3: Passed | N3: Failed | O3: Pending | P3: Blocked | Q3: NA | R3: Not execute
B4: Screen Name | C4: Frameworks · SGS Portal | K4: Round 1 | L4: =COUNTA($G$13:$G$178) | M4: =COUNTIF($M$13:$M$178,M3) | N4: =COUNTIF($M$13:$M$178,N3) | O4: =COUNTIF($M$13:$M$178,O3) | P4: =COUNTIF($M$13:$M$178,P3) | Q4: =COUNTIF($M$13:$M$178,Q3) | R4: =L4-SUM(M4:Q4)
B5: Creator | C5: Hanna | M5: =M4/$L$4 | N5: =N4/$L$4 | O5: =O4/$L$4 | P5: =P4/$L$4 | Q5: =Q4/$L$4 | R5: =R4/$L$4
B6: Created date | C6: 08/10/2026 | K6: Round 2 | L6: =COUNTA($G$13:$G$178) | M6: =COUNTIF($R$13:$R$178,M3) | N6: =COUNTIF($R$13:$R$178,N3) | O6: =COUNTIF($R$13:$R$178,O3) | P6: =COUNTIF($R$13:$R$178,P3) | Q6: =COUNTIF($R$13:$R$178,Q3) | R6: =L6-SUM(M6:Q6)
B7: Reference | C7: Figma SGS-DTP-DS · Screens 04 Frameworks · prototype · UC v4 FWK-01…07 | M7: =M6/$L$6 | N7: =N6/$L$6 | O7: =O6/$L$6 | P7: =P6/$L$6 | Q7: =Q6/$L$6 | R7: =R6/$L$6
M10: Round 1 | R10: Round 2
B11: Classification | F11: Priority | G11: TVP_ID | H11: Test case name/ Test view point | I11: Pre-condition | J11: Step | K11: Expected result | L11: Dev test | M11: Result | N11: Test person | O11: Test date | P11: Bug_ID | Q11: Remark | R11: Result | S11: Test person | T11: Test date | U11: Bug_ID | V11: Remark | W11: Open question | X11: UC
A12: No. | B12: I | C12: II | D12: III | E12: IV
A13: 1 | B13: Điều hướng - Redirect | C13: Vào danh sách - Framework list | D13: Từ menu | E13: Bấm Frameworks ở menu trái | F13: High | G13: Framework_001 | H13: Kiểm tra vào màn Frameworks từ menu trái | I13: Đăng nhập account SGS Admin | J13: 1. Bấm mục Frameworks ở menu trái | K13: - Chuyển sang màn Frameworks - Breadcrumb: Frameworks - Mục Frameworks ở menu trái được tô nền | X13: FWK-01
A14: 2 | D14: Bằng URL | E14: Đã đăng nhập | F14: Medium | G14: Framework_002 | H14: Kiểm tra mở màn Frameworks bằng URL | I14: Đăng nhập account SGS Admin | J14: 1. Mở thẳng url của màn Frameworks | K14: - Hiển thị màn Frameworks - Mục Frameworks ở menu trái được tô nền | X14: FWK-01
A15: 3 | C15: Vào chi tiết - Framework detail | D15: Từ danh sách | E15: Bấm tên framework Active | F15: High | G15: Framework_003 | H15: Kiểm tra mở chi tiết framework Active từ danh sách | I15: Đăng nhập account SGS Admin; có [Framework Active] | J15: 1. Mở màn Frameworks 2. Bấm tên [Framework Active] ở cột Framework | K15: - Chuyển sang màn chi tiết của [Framework Active] - Mục Overview ở cột bên trái được tô nền | X15: FWK-02
A16: 4 | E16: Bấm tên framework Draft | F16: High | G16: Framework_004 | H16: Kiểm tra mở bản nháp từ danh sách | I16: Đăng nhập account SGS Admin; có [Framework Draft] | J16: 1. Mở màn Frameworks 2. Bấm tên [Framework Draft] ở cột Framework | K16: - Chuyển sang màn bản nháp của [Framework Draft] - Cạnh tên framework có nhãn Draft · not active | X16: FWK-02
A17: 5 | D17: Bằng URL | E17: Mã framework hợp lệ | F17: Medium | G17: Framework_005 | H17: Kiểm tra mở chi tiết framework bằng URL | I17: Đăng nhập account SGS Admin; có [Framework Active] | J17: 1. Mở thẳng url chi tiết của [Framework Active] | K17: - Hiển thị màn chi tiết của [Framework Active] | X17: FWK-02
A18: 6 | E18: Mã framework không tồn tại | F18: Medium | G18: Framework_006 | H18: Kiểm tra mở chi tiết bằng mã framework không tồn tại | I18: Đăng nhập account SGS Admin | J18: 1. Mở url chi tiết framework với mã không tồn tại | K18: - Hiển thị thông báo: "This framework doesn’t exist It may have been removed, or it belongs to an organisation you can’t see." | X18: FWK-02
A19: 7 | B19: Danh sách framework - Framework list | C19: Tiêu đề trang - Title | D19: Hiển thị | E19: Breadcrumb, tiêu đề, mô tả | F19: Medium | G19: Framework_007 | H19: Kiểm tra phần đầu màn Frameworks | I19: Đăng nhập account SGS Admin | J19: 1. Mở màn Frameworks 2. Kiểm tra phần đầu trang | K19: - Breadcrumb: Frameworks - Tiêu đề: Frameworks - Mô tả: "Frameworks customers can activate on their scopes. Import one from the Excel template." | X19: FWK-01
